Workbook

Sheet Sheet1
A1: Nº.ID | B1: Completo | C1: Apellido | D1: Nombre | E1: 2ºNombre | F1: Dirección | G1: Dirección2 | H1: Dirección3 | I1: CP | J1: Ciudad | K1: CCAA | L1: País | M1: Tfn Casa | N1: Tfn. trabajo: | O1: Móvil | P1: Email | Q1: Género | R1: F.Nac | S1: NivelIndividual | T1: NivelDobles | U1: NivelMixto | V1: Club | W1: RatingIndividual | X1: RatingDobles | Y1: RatingMixto | Z1: Admitidos | AA1: Edad
A2: 1178913 | B2: =CONCATENATE(C2,", ", D2) -> SENCIALES DEL MORAL, ARACELI | C2: SENCIALES DEL MORAL | D2: ARACELI | K2: ANDALUZA | Q2: F | R2: 26255 | AA2: =IF(ISBLANK(R2),"",((YEAR(NOW())-YEAR(R2)))) -> 54
A3: 2079300 | B3: =CONCATENATE(C3,", ", D3) -> Rodríguez, Francisco | C3: Rodríguez | D3: Francisco | K3: ANDALUZA | Q3: M | R3: 27760 | AA3: =IF(ISBLANK(R3),"",((YEAR(NOW())-YEAR(R3)))) -> 49
A4: 4304359 | B4: =CONCATENATE(C4,", ", D4) -> HERNANDEZ SANCHEZ, SIRO | C4: HERNANDEZ SANCHEZ | D4: SIRO | K4: ANDALUZA | Q4: M | R4: 33182 | AA4: =IF(ISBLANK(R4),"",((YEAR(NOW())-YEAR(R4)))) -> 35
A5: 9307895 | B5: =CONCATENATE(C5,", ", D5) -> CARRION JIMENEZ, JOSE | C5: CARRION JIMENEZ | D5: JOSE | K5: ANDALUZA | Q5: M | R5: 33629 | AA5: =IF(ISBLANK(R5),"",((YEAR(NOW())-YEAR(R5)))) -> 33
A6: 9386568 | B6: =CONCATENATE(C6,", ", D6) -> ALVAREZ DE LA TORRE, MELQUIADES | C6: ALVAREZ DE LA TORRE | D6: MELQUIADES | K6: ANDALUZA | Q6: M | R6: 33158 | AA6: =IF(ISBLANK(R6),"",((YEAR(NOW())-YEAR(R6)))) -> 35
A7: 9425598 | B7: =CONCATENATE(C7,", ", D7) -> DOYEGA RODRIGUEZ, ALVARO | C7: DOYEGA RODRIGUEZ | D7: ALVARO | K7: ANDALUZA | Q7: M | R7: 34283 | AA7: =IF(ISBLANK(R7),"",((YEAR(NOW())-YEAR(R7)))) -> 32
A8: 9474686 | B8: =CONCATENATE(C8,", ", D8) -> TIRADO GONZALEZ, JAVIER | C8: TIRADO GONZALEZ | D8: JAVIER | K8: ANDALUZA | Q8: M | R8: 35684 | AA8: =IF(ISBLANK(R8),"",((YEAR(NOW())-YEAR(R8)))) -> 28
A9: 9483637 | B9: =CONCATENATE(C9,", ", D9) -> BATT, NATALIE | C9: BATT | D9: NATALIE | K9: ANDALUZA | Q9: F | R9: 30761 | AA9: =IF(ISBLANK(R9),"",((YEAR(NOW())-YEAR(R9)))) -> 41
A10: 9484320 | B10: =CONCATENATE(C10,", ", D10) -> LEVITSKY DE MIGUEL, PAULA | C10: LEVITSKY DE MIGUEL | D10: PAULA | K10: ANDALUZA | Q10: F | R10: 36249 | AA10: =IF(ISBLANK(R10),"",((YEAR(NOW())-YEAR(R10)))) -> 26
A11: 9510381 | B11: =CONCATENATE(C11,", ", D11) -> SYROMOLOTOV NETREBIN, YURI SANTIAGO | C11: SYROMOLOTOV NETREBIN | D11: YURI SANTIAGO | K11: ANDALUZA | Q11: M | R11: 35636 | AA11: =IF(ISBLANK(R11),"",((YEAR(NOW())-YEAR(R11)))) -> 28
A12: 9563455 | B12: =CONCATENATE(C12,", ", D12) -> RONDON LOBATO, JOSE | C12: RONDON LOBATO | D12: JOSE | K12: ANDALUZA | Q12: M | R12: 21671 | AA12: =IF(ISBLANK(R12),"",((YEAR(NOW())-YEAR(R12)))) -> 66
A13: 9573397 | B13: =CONCATENATE(C13,", ", D13) -> GARCIA ALVAREZ, ALICIA | C13: GARCIA ALVAREZ | D13: ALICIA | K13: ANDALUZA | Q13: F | R13: 34842 | AA13: =IF(ISBLANK(R13),"",((YEAR(NOW())-YEAR(R13)))) -> 30
... A86: 16969109 | B86: =CONCATENATE(C86,", ", D86) -> MIODOWNIK, DANIEL | C86: MIODOWNIK | D86: DANIEL | K86: ANDALUZA | Q86: M | R86: 20605 | AA86: =IF(ISBLANK(R86),"",((YEAR(NOW())-YEAR(R86)))) -> 69
A87: 16969159 | B87: =CONCATENATE(C87,", ", D87) -> Bernal, Jesús | C87: Bernal | D87: Jesús | K87: ANDALUZA | Q87: M | R87: 01/01/1989 | AA87: =IF(ISBLANK(R87),"",((YEAR(NOW())-YEAR(R87)))) -> 36
A88: 16969183 | B88: =CONCATENATE(C88,", ", D88) -> Gavalda, Sandra | C88: Gavalda | D88: Sandra | K88: ANDALUZA | Q88: F | R88: 01/01/1982 | AA88: =IF(ISBLANK(R88),"",((YEAR(NOW())-YEAR(R88)))) -> 43
A89: 16969191 | B89: =CONCATENATE(C89,", ", D89) -> Olmedo, Maria | C89: Olmedo | D89: Maria | K89: ANDALUZA | Q89: F | R89: 01/01/1977 | AA89: =IF(ISBLANK(R89),"",((YEAR(NOW())-YEAR(R89)))) -> 48
A90: 16969208 | B90: =CONCATENATE(C90,", ", D90) -> García, Mario | C90: García | D90: Mario | K90: ANDALUZA | Q90: M | R90: 01/01/1979 | AA90: =IF(ISBLANK(R90),"",((YEAR(NOW())-YEAR(R90)))) -> 46
A91: 16969232 | B91: =CONCATENATE(C91,", ", D91) -> Gomez, Maria Luisa | C91: Gomez | D91: Maria Luisa | K91: ANDALUZA | Q91: F | R91: 01/01/1976 | AA91: =IF(ISBLANK(R91),"",((YEAR(NOW())-YEAR(R91)))) -> 49
A92: 16969258 | B92: =CONCATENATE(C92,", ", D92) -> Carmona, Alberto | C92: Carmona | D92: Alberto | K92: ANDALUZA | Q92: M | R92: 01/01/1999 | AA92: =IF(ISBLANK(R92),"",((YEAR(NOW())-YEAR(R92)))) -> 26
A93: 16969266 | B93: =CONCATENATE(C93,", ", D93) -> Sanchez, Mari Toñi | C93: Sanchez | D93: Mari Toñi | K93: ANDALUZA | Q93: F | R93: 01/01/1981 | AA93: =IF(ISBLANK(R93),"",((YEAR(NOW())-YEAR(R93)))) -> 44
A94: 16969399 | B94: =CONCATENATE(C94,", ", D94) -> Elyse, Malka | C94: Elyse | D94: Malka | K94: ANDALUZA | Q94: F | R94: 01/01/2000 | AA94: =IF(ISBLANK(R94),"",((YEAR(NOW())-YEAR(R94)))) -> 25
A95: 16969745 | B95: =CONCATENATE(C95,", ", D95) -> Ruiz, Sergio | C95: Ruiz | D95: Sergio | K95: ANDALUZA | Q95: M | R95: 01/01/1975 | AA95: =IF(ISBLANK(R95),"",((YEAR(NOW())-YEAR(R95)))) -> 50
A96: 16969753 | B96: =CONCATENATE(C96,", ", D96) -> Pérez González, Antonio | C96: Pérez González | D96: Antonio | K96: ANDALUZA | Q96: M | R96: 01/01/1999 | AA96: =IF(ISBLANK(R96),"",((YEAR(NOW())-YEAR(R96)))) -> 26
A97: 16970403 | B97: =CONCATENATE(C97,", ", D97) -> Fernández Duque, Paco | C97: Fernández Duque | D97: Paco | K97: ANDALUZA | Q97: M | R97: 01/01/1958 | AA97: =IF(ISBLANK(R97),"",((YEAR(NOW())-YEAR(R97)))) -> 67
A98: 16970411 | B98: =CONCATENATE(C98,", ", D98) -> Lobato, Claudia | C98: Lobato | D98: Claudia | K98: ANDALUZA | Q98: F | R98: 01/01/2008 | AA98: =IF(ISBLANK(R98),"",((YEAR(NOW())-YEAR(R98)))) -> 17
... A100: 16970437 | B100: =CONCATENATE(C100,", ", D100) -> Expósito, Guillermo | C100: Expósito | D100: Guillermo | K100: ANDALUZA | Q100: M | R100: 01/01/1992 | AA100: =IF(ISBLANK(R100),"",((YEAR(NOW())-YEAR(R100)))) -> 33

Sheet Cotejar
A1: Lic Real | B1: Mutua | C1: Apellidos | D1: Nombre | E1: Territorial | F1: Fecha | G1: CHECK
A2: 4304359 | B2: 93495 | C2: Hernandez Sanchez | D2: Siro | E2: ANDALUZA | F2: 33182 | G2: =VLOOKUP(A2,Sheet1!A:A,1,FALSE) -> 4304359
A3: 9307895 | B3: 91357 | C3: Carrion Jimenez | D3: Jose | E3: ANDALUZA | F3: 33629 | G3: =VLOOKUP(A3,Sheet1!A:A,1,FALSE) -> 9307895
A4: 9386568 | B4: 93488 | C4: Alvarez De La Torre | D4: Melquiades | E4: ANDALUZA | F4: 33158 | G4: =VLOOKUP(A4,Sheet1!A:A,1,FALSE) -> 9386568
A5: 9425598 | B5: 81230 | C5: Doyega Rodriguez | D5: Alvaro | E5: ANDALUZA | F5: 34283 | G5: =VLOOKUP(A5,Sheet1!A:A,1,FALSE) -> 9425598
A6: 9474686 | B6: 81223 | C6: Tirado Gonzalez | D6: Javier | E6: ANDALUZA | F6: 35684 | G6: =VLOOKUP(A6,Sheet1!A:A,1,FALSE) -> 9474686
A7: 9510381 | B7: 40551 | C7: Syromolotov Netrebin | D7: Yuri Santiago | E7: ANDALUZA | F7: 35636 | G7: =VLOOKUP(A7,Sheet1!A:A,1,FALSE) -> 9510381
A8: 9663437 | B8: 0 | C8: Prat Callealta | D8: Guillermo | E8: ANDALUZA | F8: 36447 | G8: =VLOOKUP(A8,Sheet1!A:A,1,FALSE) -> 9663437
A9: 16913578 | B9: 95489 | C9: Serrano Ruano | D9: Alexander | E9: ANDALUZA | F9: 33382 | G9: =VLOOKUP(A9,Sheet1!A:A,1,FALSE) -> 16913578
A10: 16937065 | B10: 94419 | C10: Pereira De Mattoss | D10: Domini Elias | E10: ANDALUZA | F10: 33455 | G10: =VLOOKUP(A10,Sheet1!A:A,1,FALSE) -> 16937065
A11: 16947410 | B11: 93497 | C11: Jiménez Herrera | D11: Julián | E11: ANDALUZA | F11: 27296 | G11: =VLOOKUP(A11,Sheet1!A:A,1,FALSE) -> 16947410
A12: 16952021 | B12: 91794 | C12: Blanco Villegas | D12: Samuel | E12: ANDALUZA | F12: 37609 | G12: =VLOOKUP(A12,Sheet1!A:A,1,FALSE) -> 16952021
A13: 16952360 | B13: 93474 | C13: Casquero Herrero | D13: Antonio | E13: ANDALUZA | F13: 30828 | G13: =VLOOKUP(A13,Sheet1!A:A,1,FALSE) -> 16952360
... A79: 16953251 | B79: 75674 | C79: Yanes Cabrera | D79: Alicia | E79: ANDALUZA | F79: 25737 | G79: =VLOOKUP(A79,Sheet1!A:A,1,FALSE) -> 16953251
A80: 16969753 | C80: González Pérez | D80: Antonio | F80: 36161
C81: Lobato | D81: Claudia | F81: 36161
A82: 2079300 | C82: Rodríguez | D82: Francisco | F82: 36161
C83: Constantino | D83: Gabriela | F83: 36161
C84: Expósito | D84: Guillermo | F84: 36161
C85: Garrido | D85: Javier | F85: 36161
C86: Bernal | D86: Jesús | F86: 32509
C87: Campos | D87: Juan Pedro | F87: 36161
A88: 16954324 | C88: Gonzalez | D88: Lucas | F88: 36161
C89: S | D89: Malka | F89: 36161
C90: Sanchez | D90: Mari Toñi | F90: 29587
C91: Gomez | D91: Maria Luisa | F91: 27760
C92: Olmedo | D92: Maria | F92: 28126
C93: García | D93: Mario | F93: 28856
C94: Fernández Duque | D94: Paco | F94: 36161
A95: 16952980 | C95: Arias | D95: Ramón | F95: 36161
C96: Gavalda | D96: Sandra | F96: 29952
C97: Centeno | D97: Sergio | F97: 36161
C98: Ruiz | D98: Sergio | F98: 36161

Sheet Master Final Madrid 2024
A1: Nº.ID | B1: Completo | C1: Apellido | D1: Nombre | E1: 2ºNombre | F1: Dirección | G1: Dirección2 | H1: Dirección3 | I1: CP | J1: Ciudad | K1: CCAA | L1: País | M1: Tfn Casa | N1: Tfn. trabajo: | O1: Móvil | P1: Email | Q1: Género | R1: F.Nac | S1: NivelIndividual | T1: NivelDobles | U1: NivelMixto | V1: Club | W1: RatingIndividual | X1: RatingDobles | Y1: RatingMixto | Z1: Admitidos | AA1: Edad
A2: 10768466 | B2: Paiva Jardim, Marcello | C2: Paiva Jardim | D2: Marcello | E2: Marcello Paiva Jardim | K2: MADRID | Q2: M | S2: IM | T2: DM | U2: DX | W2: 5.0 | X2: 5.0 | Y2: 5.0
A3: 10767319 | B3: Illescas Cases, David | C3: Illescas Cases | D3: David | E3: David Illescas Cases | K3: MADRID | Q3: M | S3: IM | T3: DM | U3: DX | W3: 5.0 | X3: 5.0 | Y3: 5.0
A4: 6836467 | B4: Canyadell Fabregas, Pep | C4: Canyadell Fabregas | D4: Pep | E4: Pep Canyadell Fabregas | K4: CATALUÑA | Q4: M | S4: IM | T4: DM | U4: DX | W4: 5.0 | X4: 5.0 | Y4: 5.0
A5: 16952360 | B5: Casquero Herrero, Antonio | C5: Casquero Herrero | D5: Antonio | E5: Antonio Casquero Herrero | K5: ANDALUCIA | Q5: M | S5: IM | T5: DM | W5: 5.0 | X5: 5.0
A6: 13464954 | B6: Marcos López, Vicente | C6: Marcos López | D6: Vicente | E6: Vicente Marcos López | K6: C. VALENCIA | Q6: M | S6: IM | T6: DM | U6: DX | W6: 5.0 | X6: 5.0 | Y6: 5.0
A7: 16307820 | B7: Díaz Ibáñez, Sergio | C7: Díaz Ibáñez | D7: Sergio | E7: Sergio Díaz Ibáñez | K7: CEUTA | Q7: M | R7: 34517 | S7: IM | T7: DM | W7: 5.0 | X7: 5.0 | AA7: 30
A8: 16952980 | B8: Arias Gomar, Ramon | C8: Arias Gomar | D8: Ramon | E8: Ramon Arias Gomar | K8: ANDALUCIA | Q8: M | S8: IM | T8: DM | W8: 5.0 | X8: 5.0
A9: 6723903 | B9: De Rueda De Genover, Ignasi | C9: De Rueda De Genover | D9: Ignasi | E9: Ignasi De Rueda De Genover | K9: CATALUÑA | Q9: M | S9: IM | T9: DM | U9: DX | W9: 5.0 | X9: 5.0 | Y9: 5.0
A10: 16937065 | B10: Pereira de Mattos, Domini Elias | C10: Pereira de Mattos | D10: Domini Elias | E10: Domini Elias Pereira de Mattos | K10: ANDALUCIA | Q10: M | S10: IM | T10: DM | U10: DX | W10: 5.0 | X10: 5.0 | Y10: 5.0
A11: 11855642 | B11: Caymel Romero, Marc | C11: Caymel Romero | D11: Marc | E11: Marc Caymel Romero | K11: CATALUÑA | Q11: M | S11: IM | T11: DM | U11: DX | W11: 5.0 | X11: 5.0 | Y11: 5.0
A12: 10768565 | B12: Ruiz Calvo, Javier | C12: Ruiz Calvo | D12: Javier | E12: Javier Ruiz Calvo | K12: MADRID | Q12: M | R12: 30209 | S12: IM | T12: DM | U12: DX | W12: 5.0 | X12: 5.0 | Y12: 5.0 | AA12: 42
A13: 10768929 | B13: Vega Gutierrez, Daniel | C13: Vega Gutierrez | D13: Daniel | E13: Daniel Vega Gutierrez | K13: MADRID | Q13: M | S13: IM | T13: DM | W13: 5.0
A14: 13465308 | B14: Lillo Pellies, Sergio | C14: Lillo Pellies | D14: Sergio | E14: Sergio Lillo Pellies | K14: C. VALENCIA | Q14: M | S14: IM | T14: DM | W14: 5.0 | X14: 5.0
A15: 10768523 | B15: Horcajuelo Vicente, Alberto | C15: Horcajuelo Vicente | D15: Alberto | E15: Alberto Horcajuelo Vicente | K15: MADRID | Q15: M | S15: IM | T15: DM | W15: 5.0 | X15: 5.0
A16: 7404007 | B16: Lopez Gomez, Miguel | C16: Lopez Gomez | D16: Miguel | E16: Miguel Lopez Gomez | K16: MADRID | Q16: M | R16: 34605 | S16: IM | T16: DM | U16: DX | W16: 5.0 | X16: 5.0 | Y16: 4.5 | AA16: 30
A17: 3039890 | B17: Martinez Santonja, Esteban | C17: Martinez Santonja | D17: Esteban | E17: Esteban Martinez Santonja | K17: C. VALENCIA | Q17: M | S17: IM | T17: DM | W17: 5.0 | X17: 5.0
A18: 7238183 | B18: Mendez Dominguez, Sabrina | C18: Mendez Dominguez | D18: Sabrina | E18: Sabrina Mendez Dominguez | K18: MADRID | Q18: F | S18: IF | T18: DF | U18: DX | W18: 5.0 | X18: 5.0 | Y18: 5.0
A19: 10769042 | B19: Derbis , Nerea | C19: Derbis | D19: Nerea | E19: Nerea Derbis | K19: MADRID | Q19: F | S19: IF | T19: DF | U19: DX | W19: 5.0 | X19: 5.0 | Y19: 5.0
A20: 8318942 | B20: Chumillas Lidón, Sara | C20: Chumillas Lidón | D20: Sara | E20: Sara Chumillas Lidón | K20: MADRID | Q20: F | S20: IF | T20: DF | U20: DX | W20: 5.0 | X20: 5.0 | Y20: 5.0
A21: 10768911 | B21: Cardo Rodriguez, Rocio | C21: Cardo Rodriguez | D21: Rocio | E21: Rocio Cardo Rodriguez | K21: MADRID | Q21: F | R21: 32449 | S21: IF | T21: DF | U21: DX | W21: 5.0 | X21: 5.0 | Y21: 5.0 | AA21: 36
A22: 11855501 | B22: Caymel Romero, Claudia | C22: Caymel Romero | D22: Claudia | E22: Claudia Caymel Romero | K22: CATALUÑA | Q22: F | S22: IF | T22: DF | U22: DX | W22: 5.0 | X22: 5.0 | Y22: 5.0
A23: 10768078 | B23: Vazquez Ranz, Karina | C23: Vazquez Ranz | D23: Karina | E23: Karina Vazquez Ranz | K23: MADRID | Q23: F | S23: IF | T23: DF | U23: DX | W23: 5.0 | Y23: 5.0
A24: 9573397 | B24: García Álvarez, Alicia | C24: García Álvarez | D24: Alicia | E24: Alicia García Álvarez | K24: ANDALUCIA | Q24: F | S24: IF | T24: DF | U24: DX | W24: 4.5 | X24: 4.5 | Y24: 4.5
A25: 16951726 | B25: Millon Soto, Celia | C25: Millon Soto | D25: Celia | E25: Celia Millon Soto | K25: ANDALUCIA | Q25: F | S25: IF | T25: DF | U25: DX | W25: 4.5 | X25: 4.5 | Y25: 4.5
A26: 11855163 | B26: Serrano Lopez, Katherine Vanessa | C26: Serrano Lopez | D26: Katherine Vanessa | E26: Katherine Vanessa Serrano Lopez | K26: CATALUÑA | Q26: F | S26: IF | T26: DF | U26: DX | W26: 4.5 | X26: 4.5 | Y26: 4.5
A27: 10768804 | B27: De Miguel Gonzalez, Maria | C27: De Miguel Gonzalez | D27: Maria | E27: Maria De Miguel Gonzalez | K27: MADRID | Q27: F | R27: 31433 | S27: IF | T27: DF | W27: 4.5 | AA27: 38
A28: 10767418 | B28: Bitaine , Alex | C28: Bitaine | D28: Alex | E28: Alex Bitaine | K28: MADRID | Q28: F | S28: IF | T28: DF | U28: DX | W28: 4.5 | X28: 4.5 | Y28: 4.5
A29: 10058320 | B29: Cartagena, Carlota | C29: Cartagena | D29: Carlota | E29: Carlota Cartagena | K29: MADRID | Q29: F | R29: 35899 | S29: IF | T29: DF | W29: 4.5 | AA29: 26
A30: 10767161 | B30: Fierro Gonzalez, Monica | C30: Fierro Gonzalez | D30: Monica | E30: Monica Fierro Gonzalez | K30: MADRID | Q30: F | U30: DX | Y30: 4.5
A31: 16953045 | B31: Varo Martínez, Vanessa | C31: Varo Martínez | D31: Vanessa | E31: Vanessa Varo Martínez | K31: ANDALUCIA | Q31: F | S31: IF | T31: DF | U31: DX | W31: 4.5 | X31: 4.5 | Y31: 4.5
A32: 11087344 | B32: Dominguez Luna, Sheila | C32: Dominguez Luna | D32: Sheila | E32: Sheila Dominguez Luna | K32: CATALUÑA | Q32: F | S32: IF | W32: 3.5
A33: 11855626 | B33: Castells Carbonell, Anna | C33: Castells Carbonell | D33: Anna | E33: Anna Castells Carbonell | K33: CATALUÑA | Q33: F | S33: IF | T33: DF | W33: 3.5
A34: 11856046 | B34: Ferrer Ramon, Marta | C34: Ferrer Ramon | D34: Marta | E34: Marta Ferrer Ramon | K34: CATALUÑA | Q34: F | S34: IF | T34: DF | W34: 3.5
A35: 11855288 | B35: Hernández , Laura | C35: Hernández | D35: Laura | E35: Laura Hernández | K35: CATALUÑA | Q35: F | S35: IF | T35: DF | W35: 3.5
A36: 16953342 | B36: Gallego Ruiz-Mateos, Javier | C36: Gallego Ruiz-Mateos | D36: Javier | E36: Javier Gallego Ruiz-Mateos | K36: ANDALUCIA | Q36: M | S36: IM | T36: DM | U36: DX | W36: 5.0 | X36: 5.0 | Y36: 5.0
A37: 10768961 | B37: Prieto Perez, Álvaro | C37: Prieto Perez | D37: Álvaro | E37: Álvaro Prieto Perez | K37: MADRID | Q37: M | R37: 29946 | S37: IM | T37: DM | U37: DX | W37: 5.0 | X37: 5.0 | Y37: 5.0 | AA37: 43
A38: 10768185 | B38: Cardenas Santa, Ernesto | C38: Cardenas Santa | D38: Ernesto | E38: Ernesto Cardenas Santa | Q38: M | S38: IM | T38: DM | U38: DX | W38: 5.0 | X38: 5.0 | Y38: 5.0
A39: 10767103 | B39: Perez Soto, Carlos Alberto | C39: Perez Soto | D39: Carlos Alberto | E39: Carlos Alberto Perez Soto | K39: MADRID | Q39: M | R39: 28564 | S39: IM | T39: DM | U39: DX | W39: 5.0 | X39: 5.0 | Y39: 5.0 | AA39: 46
A40: 16913578 | B40: Serrano Ruano, Alexander | C40: Serrano Ruano | D40: Alexander | E40: Alexander Serrano Ruano | Q40: M | S40: IM | T40: DM | W40: 5.0 | X40: 5.0
...

Sheet CTO.ANDALUCIA 2025
A1: Nº.ID | B1: Completo | C1: Apellido | D1: Nombre | E1: 2ºNombre | F1: Dirección | G1: Dirección2 | H1: Dirección3 | I1: CP | J1: Ciudad | K1: CCAA | L1: País | M1: Tfn Casa | N1: Tfn. trabajo: | O1: Móvil | P1: Email | Q1: Género | R1: F.Nac | S1: NivelIndividual | T1: NivelDobles | U1: NivelMixto | V1: Club | W1: RatingIndividual | X1: RatingDobles | Y1: RatingMixto | Z1: Admitidos | AA1: Edad
A2: 1178913 | B2: SENCIALES DEL MORAL, ARACELI | C2: SENCIALES DEL MORAL | D2: ARACELI | K2: ANDALUZA | Q2: F | R2: 26255 | AA2: 54
A3: 2079300 | B3: Rodríguez, Francisco | C3: Rodríguez | D3: Francisco | K3: ANDALUZA | Q3: M | R3: 27760 | AA3: 49
A4: 4304359 | B4: HERNANDEZ SANCHEZ, SIRO | C4: HERNANDEZ SANCHEZ | D4: SIRO | K4: ANDALUZA | Q4: M | R4: 33182 | AA4: 35
A5: 9307895 | B5: CARRION JIMENEZ, JOSE | C5: CARRION JIMENEZ | D5: JOSE | K5: ANDALUZA | Q5: M | R5: 33629 | AA5: 33
A6: 9386568 | B6: ALVAREZ DE LA TORRE, MELQUIADES | C6: ALVAREZ DE LA TORRE | D6: MELQUIADES | K6: ANDALUZA | Q6: M | R6: 33158 | AA6: 35
A7: 9425598 | B7: DOYEGA RODRIGUEZ, ALVARO | C7: DOYEGA RODRIGUEZ | D7: ALVARO | K7: ANDALUZA | Q7: M | R7: 34283 | AA7: 32
A8: 9474686 | B8: TIRADO GONZALEZ, JAVIER | C8: TIRADO GONZALEZ | D8: JAVIER | K8: ANDALUZA | Q8: M | R8: 35684 | AA8: 28
A9: 9483637 | B9: BATT, NATALIE | C9: BATT | D9: NATALIE | K9: ANDALUZA | Q9: F | R9: 30761 | AA9: 41
A10: 9484320 | B10: LEVITSKY DE MIGUEL, PAULA | C10: LEVITSKY DE MIGUEL | D10: PAULA | K10: ANDALUZA | Q10: F | R10: 36249 | AA10: 26
A11: 9510381 | B11: SYROMOLOTOV NETREBIN, YURI SANTIAGO | C11: SYROMOLOTOV NETREBIN | D11: YURI SANTIAGO | K11: ANDALUZA | Q11: M | R11: 35636 | AA11: 28
A12: 9563455 | B12: RONDON LOBATO, JOSE | C12: RONDON LOBATO | D12: JOSE | K12: ANDALUZA | Q12: M | R12: 21671 | AA12: 66
A13: 9573397 | B13: GARCIA ALVAREZ, ALICIA | C13: GARCIA ALVAREZ | D13: ALICIA | K13: ANDALUZA | Q13: F | R13: 34842 | AA13: 30
... A86: 16969109 | B86: MIODOWNIK, DANIEL | C86: MIODOWNIK | D86: DANIEL | K86: ANDALUZA | Q86: M | R86: 20605 | AA86: 69
A87: 16969159 | B87: Bernal, Jesús | C87: Bernal | D87: Jesús | K87: ANDALUZA | Q87: M | R87: 01/01/1989 | AA87: 36
A88: 16969183 | B88: Gavalda, Sandra | C88: Gavalda | D88: Sandra | K88: ANDALUZA | Q88: F | R88: 01/01/1982 | AA88: 43
A89: 16969191 | B89: Olmedo, Maria | C89: Olmedo | D89: Maria | K89: ANDALUZA | Q89: F | R89: 01/01/1977 | AA89: 48
A90: 16969208 | B90: García, Mario | C90: García | D90: Mario | K90: ANDALUZA | Q90: M | R90: 01/01/1979 | AA90: 46
A91: 16969232 | B91: Gomez, Maria Luisa | C91: Gomez | D91: Maria Luisa | K91: ANDALUZA | Q91: F | R91: 01/01/1976 | AA91: 49
A92: 16969258 | B92: Carmona, Alberto | C92: Carmona | D92: Alberto | K92: ANDALUZA | Q92: M | R92: 01/01/1999 | AA92: 26
A93: 16969266 | B93: Sanchez, Mari Toñi | C93: Sanchez | D93: Mari Toñi | K93: ANDALUZA | Q93: F | R93: 01/01/1981 | AA93: 44
A94: 16969399 | B94: Elyse, Malka | C94: Elyse | D94: Malka | K94: ANDALUZA | Q94: F | R94: 01/01/2000 | AA94: 25
A95: 16969745 | B95: Ruiz, Sergio | C95: Ruiz | D95: Sergio | K95: ANDALUZA | Q95: M | R95: 01/01/1975 | AA95: 50
A96: 16969753 | B96: Pérez González, Antonio | C96: Pérez González | D96: Antonio | K96: ANDALUZA | Q96: M | R96: 01/01/1999 | AA96: 26
A97: 16970403 | B97: Fernández Duque, Paco | C97: Fernández Duque | D97: Paco | K97: ANDALUZA | Q97: M | R97: 01/01/1958 | AA97: 67
A98: 16970411 | B98: Lobato, Claudia | C98: Lobato | D98: Claudia | K98: ANDALUZA | Q98: F | R98: 01/01/2008 | AA98: 17
... A100: 16970437 | B100: Expósito, Guillermo | C100: Expósito | D100: Guillermo | K100: ANDALUZA | Q100: M | R100: 01/01/1992 | AA100: 33

Sheet FORMULAS
A1: Nº.ID | B1: Completo | C1: Apellido | D1: Nombre | E1: 2ºNombre | F1: Dirección | G1: Dirección2 | H1: Dirección3 | I1: CP | J1: Ciudad | K1: CCAA | L1: País | M1: Tfn Casa | N1: Tfn. trabajo: | O1: Móvil | P1: Email | Q1: Género | R1: F.Nac | S1: NivelIndividual | T1: NivelDobles | U1: NivelMixto | V1: Club | W1: RatingIndividual | X1: RatingDobles | Y1: RatingMixto | Z1: Admitidos | AA1: Edad
A2: 1178913 | B2: =IF(VLOOKUP($A2,Sheet1!$A:$AA,MATCH(B$1,Sheet1!$A$1:$AA$1,0),FALSE)=0,"",VLOOKUP($A2,Sheet1!$A:$AA,MATCH(B$1,Sheet1!$A$1:$AA$1,0),FALSE)) -> SENCIALES DEL MORAL, ARACELI | C2: =IF(VLOOKUP($A2,Sheet1!$A:$AA,MATCH(C$1,Sheet1!$A$1:$AA$1,0),FALSE)=0,"",VLOOKUP($A2,Sheet1!$A:$AA,MATCH(C$1,Sheet1!$A$1:$AA$1,0),FALSE)) -> SENCIALES DEL MORAL | D2: =IF(VLOOKUP($A2,Sheet1!$A:$AA,MATCH(D$1,Sheet1!$A$1:$AA$1,0),FALSE)=0,"",VLOOKUP($A2,Sheet1!$A:$AA,MATCH(D$1,Sheet1!$A$1:$AA$1,0),FALSE)) -> ARACELI | E2: =IF(VLOOKUP($A2,Sheet1!$A:$AA,MATCH(E$1,Sheet1!$A$1:$AA$1,0),FALSE)=0,"",VLOOKUP($A2,Sheet1!$A:$AA,MATCH(E$1,Sheet1!$A$1:$AA$1,0),FALSE)) | F2: =IF(VLOOKUP($A2,Sheet1!$A:$AA,MATCH(F$1,Sheet1!$A$1:$AA$1,0),FALSE)=0,"",VLOOKUP($A2,Sheet1!$A:$AA,MATCH(F$1,Sheet1!$A$1:$AA$1,0),FALSE)) | G2: =IF(VLOOKUP($A2,Sheet1!$A:$AA,MATCH(G$1,Sheet1!$A$1:$AA$1,0),FALSE)=0,"",VLOOKUP($A2,Sheet1!$A:$AA,MATCH(G$1,Sheet1!$A$1:$AA$1,0),FALSE)) | H2: =IF(VLOOKUP($A2,Sheet1!$A:$AA,MATCH(H$1,Sheet1!$A$1:$AA$1,0),FALSE)=0,"",VLOOKUP($A2,Sheet1!$A:$AA,MATCH(H$1,Sheet1!$A$1:$AA$1,0),FALSE)) | I2: =IF(VLOOKUP($A2,Sheet1!$A:$AA,MATCH(I$1,Sheet1!$A$1:$AA$1,0),FALSE)=0,"",VLOOKUP($A2,Sheet1!$A:$AA,MATCH(I$1,Sheet1!$A$1:$AA$1,0),FALSE)) | ... R2: =IF(VLOOKUP($A2,Sheet1!$A:$AA,MATCH(R$1,Sheet1!$A$1:$AA$1,0),FALSE)=0,"",VLOOKUP($A2,Sheet1!$A:$AA,MATCH(R$1,Sheet1!$A$1:$AA$1,0),FALSE)) -> 26255 | AA2: =IF(VLOOKUP($A2,Sheet1!$A:$AA,MATCH(AA$1,Sheet1!$A$1:$AA$1,0),FALSE)=0,"",VLOOKUP($A2,Sheet1!$A:$AA,MATCH(AA$1,Sheet1!$A$1:$AA$1,0),FALSE)) -> 54
A3: 2079300 | B3: =IF(VLOOKUP($A3,Sheet1!$A:$AA,MATCH(B$1,Sheet1!$A$1:$AA$1,0),FALSE)=0,"",VLOOKUP($A3,Sheet1!$A:$AA,MATCH(B$1,Sheet1!$A$1:$AA$1,0),FALSE)) -> Rodríguez, Francisco | C3: =IF(VLOOKUP($A3,Sheet1!$A:$AA,MATCH(C$1,Sheet1!$A$1:$AA$1,0),FALSE)=0,"",VLOOKUP($A3,Sheet1!$A:$AA,MATCH(C$1,Sheet1!$A$1:$AA$1,0),FALSE)) -> Rodríguez | D3: =IF(VLOOKUP($A3,Sheet1!$A:$AA,MATCH(D$1,Sheet1!$A$1:$AA$1,0),FALSE)=0,"",VLOOKUP($A3,Sheet1!$A:$AA,MATCH(D$1,Sheet1!$A$1:$AA$1,0),FALSE)) -> Francisco | E3: =IF(VLOOKUP($A3,Sheet1!$A:$AA,MATCH(E$1,Sheet1!$A$1:$AA$1,0),FALSE)=0,"",VLOOKUP($A3,Sheet1!$A:$AA,MATCH(E$1,Sheet1!$A$1:$AA$1,0),FALSE)) | F3: =IF(VLOOKUP($A3,Sheet1!$A:$AA,MATCH(F$1,Sheet1!$A$1:$AA$1,0),FALSE)=0,"",VLOOKUP($A3,Sheet1!$A:$AA,MATCH(F$1,Sheet1!$A$1:$AA$1,0),FALSE)) | G3: =IF(VLOOKUP($A3,Sheet1!$A:$AA,MATCH(G$1,Sheet1!$A$1:$AA$1,0),FALSE)=0,"",VLOOKUP($A3,Sheet1!$A:$AA,MATCH(G$1,Sheet1!$A$1:$AA$1,0),FALSE)) | H3: =IF(VLOOKUP($A3,Sheet1!$A:$AA,MATCH(H$1,Sheet1!$A$1:$AA$1,0),FALSE)=0,"",VLOOKUP($A3,Sheet1!$A:$AA,MATCH(H$1,Sheet1!$A$1:$AA$1,0),FALSE)) | I3: =IF(VLOOKUP($A3,Sheet1!$A:$AA,MATCH(I$1,Sheet1!$A$1:$AA$1,0),FALSE)=0,"",VLOOKUP($A3,Sheet1!$A:$AA,MATCH(I$1,Sheet1!$A$1:$AA$1,0),FALSE)) | ... R3: =IF(VLOOKUP($A3,Sheet1!$A:$AA,MATCH(R$1,Sheet1!$A$1:$AA$1,0),FALSE)=0,"",VLOOKUP($A3,Sheet1!$A:$AA,MATCH(R$1,Sheet1!$A$1:$AA$1,0),FALSE)) -> 27760 | AA3: =IF(VLOOKUP($A3,Sheet1!$A:$AA,MATCH(AA$1,Sheet1!$A$1:$AA$1,0),FALSE)=0,"",VLOOKUP($A3,Sheet1!$A:$AA,MATCH(AA$1,Sheet1!$A$1:$AA$1,0),FALSE)) -> 49
A4: 4304359 | B4: =IF(VLOOKUP($A4,Sheet1!$A:$AA,MATCH(B$1,Sheet1!$A$1:$AA$1,0),FALSE)=0,"",VLOOKUP($A4,Sheet1!$A:$AA,MATCH(B$1,Sheet1!$A$1:$AA$1,0),FALSE)) -> HERNANDEZ SANCHEZ, SIRO | C4: =IF(VLOOKUP($A4,Sheet1!$A:$AA,MATCH(C$1,Sheet1!$A$1:$AA$1,0),FALSE)=0,"",VLOOKUP($A4,Sheet1!$A:$AA,MATCH(C$1,Sheet1!$A$1:$AA$1,0),FALSE)) -> HERNANDEZ SANCHEZ | D4: =IF(VLOOKUP($A4,Sheet1!$A:$AA,MATCH(D$1,Sheet1!$A$1:$AA$1,0),FALSE)=0,"",VLOOKUP($A4,Sheet1!$A:$AA,MATCH(D$1,Sheet1!$A$1:$AA$1,0),FALSE)) -> SIRO | E4: =IF(VLOOKUP($A4,Sheet1!$A:$AA,MATCH(E$1,Sheet1!$A$1:$AA$1,0),FALSE)=0,"",VLOOKUP($A4,Sheet1!$A:$AA,MATCH(E$1,Sheet1!$A$1:$AA$1,0),FALSE)) | F4: =IF(VLOOKUP($A4,Sheet1!$A:$AA,MATCH(F$1,Sheet1!$A$1:$AA$1,0),FALSE)=0,"",VLOOKUP($A4,Sheet1!$A:$AA,MATCH(F$1,Sheet1!$A$1:$AA$1,0),FALSE)) | G4: =IF(VLOOKUP($A4,Sheet1!$A:$AA,MATCH(G$1,Sheet1!$A$1:$AA$1,0),FALSE)=0,"",VLOOKUP($A4,Sheet1!$A:$AA,MATCH(G$1,Sheet1!$A$1:$AA$1,0),FALSE)) | H4: =IF(VLOOKUP($A4,Sheet1!$A:$AA,MATCH(H$1,Sheet1!$A$1:$AA$1,0),FALSE)=0,"",VLOOKUP($A4,Sheet1!$A:$AA,MATCH(H$1,Sheet1!$A$1:$AA$1,0),FALSE)) | I4: =IF(VLOOKUP($A4,Sheet1!$A:$AA,MATCH(I$1,Sheet1!$A$1:$AA$1,0),FALSE)=0,"",VLOOKUP($A4,Sheet1!$A:$AA,MATCH(I$1,Sheet1!$A$1:$AA$1,0),FALSE)) | ... R4: =IF(VLOOKUP($A4,Sheet1!$A:$AA,MATCH(R$1,Sheet1!$A$1:$AA$1,0),FALSE)=0,"",VLOOKUP($A4,Sheet1!$A:$AA,MATCH(R$1,Sheet1!$A$1:$AA$1,0),FALSE)) -> 33182 | AA4: =IF(VLOOKUP($A4,Sheet1!$A:$AA,MATCH(AA$1,Sheet1!$A$1:$AA$1,0),FALSE)=0,"",VLOOKUP($A4,Sheet1!$A:$AA,MATCH(AA$1,Sheet1!$A$1:$AA$1,0),FALSE)) -> 35
A5: 9307895 | B5: =IF(VLOOKUP($A5,Sheet1!$A:$AA,MATCH(B$1,Sheet1!$A$1:$AA$1,0),FALSE)=0,"",VLOOKUP($A5,Sheet1!$A:$AA,MATCH(B$1,Sheet1!$A$1:$AA$1,0),FALSE)) -> CARRION JIMENEZ, JOSE | C5: =IF(VLOOKUP($A5,Sheet1!$A:$AA,MATCH(C$1,Sheet1!$A$1:$AA$1,0),FALSE)=0,"",VLOOKUP($A5,Sheet1!$A:$AA,MATCH(C$1,Sheet1!$A$1:$AA$1,0),FALSE)) -> CARRION JIMENEZ | D5: =IF(VLOOKUP($A5,Sheet1!$A:$AA,MATCH(D$1,Sheet1!$A$1:$AA$1,0),FALSE)=0,"",VLOOKUP($A5,Sheet1!$A:$AA,MATCH(D$1,Sheet1!$A$1:$AA$1,0),FALSE)) -> JOSE | E5: =IF(VLOOKUP($A5,Sheet1!$A:$AA,MATCH(E$1,Sheet1!$A$1:$AA$1,0),FALSE)=0,"",VLOOKUP($A5,Sheet1!$A:$AA,MATCH(E$1,Sheet1!$A$1:$AA$1,0),FALSE)) | F5: =IF(VLOOKUP($A5,Sheet1!$A:$AA,MATCH(F$1,Sheet1!$A$1:$AA$1,0),FALSE)=0,"",VLOOKUP($A5,Sheet1!$A:$AA,MATCH(F$1,Sheet1!$A$1:$AA$1,0),FALSE)) | G5: =IF(VLOOKUP($A5,Sheet1!$A:$AA,MATCH(G$1,Sheet1!$A$1:$AA$1,0),FALSE)=0,"",VLOOKUP($A5,Sheet1!$A:$AA,MATCH(G$1,Sheet1!$A$1:$AA$1,0),FALSE)) | H5: =IF(VLOOKUP($A5,Sheet1!$A:$AA,MATCH(H$1,Sheet1!$A$1:$AA$1,0),FALSE)=0,"",VLOOKUP($A5,Sheet1!$A:$AA,MATCH(H$1,Sheet1!$A$1:$AA$1,0),FALSE)) | I5: =IF(VLOOKUP($A5,Sheet1!$A:$AA,MATCH(I$1,Sheet1!$A$1:$AA$1,0),FALSE)=0,"",VLOOKUP($A5,Sheet1!$A:$AA,MATCH(I$1,Sheet1!$A$1:$AA$1,0),FALSE)) | ... R5: =IF(VLOOKUP($A5,Sheet1!$A:$AA,MATCH(R$1,Sheet1!$A$1:$AA$1,0),FALSE)=0,"",VLOOKUP($A5,Sheet1!$A:$AA,MATCH(R$1,Sheet1!$A$1:$AA$1,0),FALSE)) -> 33629 | AA5: =IF(VLOOKUP($A5,Sheet1!$A:$AA,MATCH(AA$1,Sheet1!$A$1:$AA$1,0),FALSE)=0,"",VLOOKUP($A5,Sheet1!$A:$AA,MATCH(AA$1,Sheet1!$A$1:$AA$1,0),FALSE)) -> 33
A6: 9386568 | B6: =IF(VLOOKUP($A6,Sheet1!$A:$AA,MATCH(B$1,Sheet1!$A$1:$AA$1,0),FALSE)=0,"",VLOOKUP($A6,Sheet1!$A:$AA,MATCH(B$1,Sheet1!$A$1:$AA$1,0),FALSE)) -> ALVAREZ DE LA TORRE, MELQUIADES | C6: =IF(VLOOKUP($A6,Sheet1!$A:$AA,MATCH(C$1,Sheet1!$A$1:$AA$1,0),FALSE)=0,"",VLOOKUP($A6,Sheet1!$A:$AA,MATCH(C$1,Sheet1!$A$1:$AA$1,0),FALSE)) -> ALVAREZ DE LA TORRE | D6: =IF(VLOOKUP($A6,Sheet1!$A:$AA,MATCH(D$1,Sheet1!$A$1:$AA$1,0),FALSE)=0,"",VLOOKUP($A6,Sheet1!$A:$AA,MATCH(D$1,Sheet1!$A$1:$AA$1,0),FALSE)) -> MELQUIADES | E6: =IF(VLOOKUP($A6,Sheet1!$A:$AA,MATCH(E$1,Sheet1!$A$1:$AA$1,0),FALSE)=0,"",VLOOKUP($A6,Sheet1!$A:$AA,MATCH(E$1,Sheet1!$A$1:$AA$1,0),FALSE)) | F6: =IF(VLOOKUP($A6,Sheet1!$A:$AA,MATCH(F$1,Sheet1!$A$1:$AA$1,0),FALSE)=0,"",VLOOKUP($A6,Sheet1!$A:$AA,MATCH(F$1,Sheet1!$A$1:$AA$1,0),FALSE)) | G6: =IF(VLOOKUP($A6,Sheet1!$A:$AA,MATCH(G$1,Sheet1!$A$1:$AA$1,0),FALSE)=0,"",VLOOKUP($A6,Sheet1!$A:$AA,MATCH(G$1,Sheet1!$A$1:$AA$1,0),FALSE)) | H6: =IF(VLOOKUP($A6,Sheet1!$A:$AA,MATCH(H$1,Sheet1!$A$1:$AA$1,0),FALSE)=0,"",VLOOKUP($A6,Sheet1!$A:$AA,MATCH(H$1,Sheet1!$A$1:$AA$1,0),FALSE)) | I6: =IF(VLOOKUP($A6,Sheet1!$A:$AA,MATCH(I$1,Sheet1!$A$1:$AA$1,0),FALSE)=0,"",VLOOKUP($A6,Sheet1!$A:$AA,MATCH(I$1,Sheet1!$A$1:$AA$1,0),FALSE)) | ... R6: =IF(VLOOKUP($A6,Sheet1!$A:$AA,MATCH(R$1,Sheet1!$A$1:$AA$1,0),FALSE)=0,"",VLOOKUP($A6,Sheet1!$A:$AA,MATCH(R$1,Sheet1!$A$1:$AA$1,0),FALSE)) -> 33158 | AA6: =IF(VLOOKUP($A6,Sheet1!$A:$AA,MATCH(AA$1,Sheet1!$A$1:$AA$1,0),FALSE)=0,"",VLOOKUP($A6,Sheet1!$A:$AA,MATCH(AA$1,Sheet1!$A$1:$AA$1,0),FALSE)) -> 35
A7: 9425598 | B7: =IF(VLOOKUP($A7,Sheet1!$A:$AA,MATCH(B$1,Sheet1!$A$1:$AA$1,0),FALSE)=0,"",VLOOKUP($A7,Sheet1!$A:$AA,MATCH(B$1,Sheet1!$A$1:$AA$1,0),FALSE)) -> DOYEGA RODRIGUEZ, ALVARO | C7: =IF(VLOOKUP($A7,Sheet1!$A:$AA,MATCH(C$1,Sheet1!$A$1:$AA$1,0),FALSE)=0,"",VLOOKUP($A7,Sheet1!$A:$AA,MATCH(C$1,Sheet1!$A$1:$AA$1,0),FALSE)) -> DOYEGA RODRIGUEZ | D7: =IF(VLOOKUP($A7,Sheet1!$A:$AA,MATCH(D$1,Sheet1!$A$1:$AA$1,0),FALSE)=0,"",VLOOKUP($A7,Sheet1!$A:$AA,MATCH(D$1,Sheet1!$A$1:$AA$1,0),FALSE)) -> ALVARO | E7: =IF(VLOOKUP($A7,Sheet1!$A:$AA,MATCH(E$1,Sheet1!$A$1:$AA$1,0),FALSE)=0,"",VLOOKUP($A7,Sheet1!$A:$AA,MATCH(E$1,Sheet1!$A$1:$AA$1,0),FALSE)) | F7: =IF(VLOOKUP($A7,Sheet1!$A:$AA,MATCH(F$1,Sheet1!$A$1:$AA$1,0),FALSE)=0,"",VLOOKUP($A7,Sheet1!$A:$AA,MATCH(F$1,Sheet1!$A$1:$AA$1,0),FALSE)) | G7: =IF(VLOOKUP($A7,Sheet1!$A:$AA,MATCH(G$1,Sheet1!$A$1:$AA$1,0),FALSE)=0,"",VLOOKUP($A7,Sheet1!$A:$AA,MATCH(G$1,Sheet1!$A$1:$AA$1,0),FALSE)) | H7: =IF(VLOOKUP($A7,Sheet1!$A:$AA,MATCH(H$1,Sheet1!$A$1:$AA$1,0),FALSE)=0,"",VLOOKUP($A7,Sheet1!$A:$AA,MATCH(H$1,Sheet1!$A$1:$AA$1,0),FALSE)) | I7: =IF(VLOOKUP($A7,Sheet1!$A:$AA,MATCH(I$1,Sheet1!$A$1:$AA$1,0),FALSE)=0,"",VLOOKUP($A7,Sheet1!$A:$AA,MATCH(I$1,Sheet1!$A$1:$AA$1,0),FALSE)) | ... R7: =IF(VLOOKUP($A7,Sheet1!$A:$AA,MATCH(R$1,Sheet1!$A$1:$AA$1,0),FALSE)=0,"",VLOOKUP($A7,Sheet1!$A:$AA,MATCH(R$1,Sheet1!$A$1:$AA$1,0),FALSE)) -> 34283 | AA7: =IF(VLOOKUP($A7,Sheet1!$A:$AA,MATCH(AA$1,Sheet1!$A$1:$AA$1,0),FALSE)=0,"",VLOOKUP($A7,Sheet1!$A:$AA,MATCH(AA$1,Sheet1!$A$1:$AA$1,0),FALSE)) -> 32
A8: 9474686 | B8: =IF(VLOOKUP($A8,Sheet1!$A:$AA,MATCH(B$1,Sheet1!$A$1:$AA$1,0),FALSE)=0,"",VLOOKUP($A8,Sheet1!$A:$AA,MATCH(B$1,Sheet1!$A$1:$AA$1,0),FALSE)) -> TIRADO GONZALEZ, JAVIER | C8: =IF(VLOOKUP($A8,Sheet1!$A:$AA,MATCH(C$1,Sheet1!$A$1:$AA$1,0),FALSE)=0,"",VLOOKUP($A8,Sheet1!$A:$AA,MATCH(C$1,Sheet1!$A$1:$AA$1,0),FALSE)) -> TIRADO GONZALEZ | D8: =IF(VLOOKUP($A8,Sheet1!$A:$AA,MATCH(D$1,Sheet1!$A$1:$AA$1,0),FALSE)=0,"",VLOOKUP($A8,Sheet1!$A:$AA,MATCH(D$1,Sheet1!$A$1:$AA$1,0),FALSE)) -> JAVIER | E8: =IF(VLOOKUP($A8,Sheet1!$A:$AA,MATCH(E$1,Sheet1!$A$1:$AA$1,0),FALSE)=0,"",VLOOKUP($A8,Sheet1!$A:$AA,MATCH(E$1,Sheet1!$A$1:$AA$1,0),FALSE)) | F8: =IF(VLOOKUP($A8,Sheet1!$A:$AA,MATCH(F$1,Sheet1!$A$1:$AA$1,0),FALSE)=0,"",VLOOKUP($A8,Sheet1!$A:$AA,MATCH(F$1,Sheet1!$A$1:$AA$1,0),FALSE)) | G8: =IF(VLOOKUP($A8,Sheet1!$A:$AA,MATCH(G$1,Sheet1!$A$1:$AA$1,0),FALSE)=0,"",VLOOKUP($A8,Sheet1!$A:$AA,MATCH(G$1,Sheet1!$A$1:$AA$1,0),FALSE)) | H8: =IF(VLOOKUP($A8,Sheet1!$A:$AA,MATCH(H$1,Sheet1!$A$1:$AA$1,0),FALSE)=0,"",VLOOKUP($A8,Sheet1!$A:$AA,MATCH(H$1,Sheet1!$A$1:$AA$1,0),FALSE)) | I8: =IF(VLOOKUP($A8,Sheet1!$A:$AA,MATCH(I$1,Sheet1!$A$1:$AA$1,0),FALSE)=0,"",VLOOKUP($A8,Sheet1!$A:$AA,MATCH(I$1,Sheet1!$A$1:$AA$1,0),FALSE)) | ... R8: =IF(VLOOKUP($A8,Sheet1!$A:$AA,MATCH(R$1,Sheet1!$A$1:$AA$1,0),FALSE)=0,"",VLOOKUP($A8,Sheet1!$A:$AA,MATCH(R$1,Sheet1!$A$1:$AA$1,0),FALSE)) -> 35684 | AA8: =IF(VLOOKUP($A8,Sheet1!$A:$AA,MATCH(AA$1,Sheet1!$A$1:$AA$1,0),FALSE)=0,"",VLOOKUP($A8,Sheet1!$A:$AA,MATCH(AA$1,Sheet1!$A$1:$AA$1,0),FALSE)) -> 28
A9: 9483637 | B9: =IF(VLOOKUP($A9,Sheet1!$A:$AA,MATCH(B$1,Sheet1!$A$1:$AA$1,0),FALSE)=0,"",VLOOKUP($A9,Sheet1!$A:$AA,MATCH(B$1,Sheet1!$A$1:$AA$1,0),FALSE)) -> BATT, NATALIE | C9: =IF(VLOOKUP($A9,Sheet1!$A:$AA,MATCH(C$1,Sheet1!$A$1:$AA$1,0),FALSE)=0,"",VLOOKUP($A9,Sheet1!$A:$AA,MATCH(C$1,Sheet1!$A$1:$AA$1,0),FALSE)) -> BATT | D9: =IF(VLOOKUP($A9,Sheet1!$A:$AA,MATCH(D$1,Sheet1!$A$1:$AA$1,0),FALSE)=0,"",VLOOKUP($A9,Sheet1!$A:$AA,MATCH(D$1,Sheet1!$A$1:$AA$1,0),FALSE)) -> NATALIE | E9: =IF(VLOOKUP($A9,Sheet1!$A:$AA,MATCH(E$1,Sheet1!$A$1:$AA$1,0),FALSE)=0,"",VLOOKUP($A9,Sheet1!$A:$AA,MATCH(E$1,Sheet1!$A$1:$AA$1,0),FALSE)) | F9: =IF(VLOOKUP($A9,Sheet1!$A:$AA,MATCH(F$1,Sheet1!$A$1:$AA$1,0),FALSE)=0,"",VLOOKUP($A9,Sheet1!$A:$AA,MATCH(F$1,Sheet1!$A$1:$AA$1,0),FALSE)) | G9: =IF(VLOOKUP($A9,Sheet1!$A:$AA,MATCH(G$1,Sheet1!$A$1:$AA$1,0),FALSE)=0,"",VLOOKUP($A9,Sheet1!$A:$AA,MATCH(G$1,Sheet1!$A$1:$AA$1,0),FALSE)) | H9: =IF(VLOOKUP($A9,Sheet1!$A:$AA,MATCH(H$1,Sheet1!$A$1:$AA$1,0),FALSE)=0,"",VLOOKUP($A9,Sheet1!$A:$AA,MATCH(H$1,Sheet1!$A$1:$AA$1,0),FALSE)) | I9: =IF(VLOOKUP($A9,Sheet1!$A:$AA,MATCH(I$1,Sheet1!$A$1:$AA$1,0),FALSE)=0,"",VLOOKUP($A9,Sheet1!$A:$AA,MATCH(I$1,Sheet1!$A$1:$AA$1,0),FALSE)) | ... R9: =IF(VLOOKUP($A9,Sheet1!$A:$AA,MATCH(R$1,Sheet1!$A$1:$AA$1,0),FALSE)=0,"",VLOOKUP($A9,Sheet1!$A:$AA,MATCH(R$1,Sheet1!$A$1:$AA$1,0),FALSE)) -> 30761 | AA9: =IF(VLOOKUP($A9,Sheet1!$A:$AA,MATCH(AA$1,Sheet1!$A$1:$AA$1,0),FALSE)=0,"",VLOOKUP($A9,Sheet1!$A:$AA,MATCH(AA$1,Sheet1!$A$1:$AA$1,0),FALSE)) -> 41
A10: 9484320 | B10: =IF(VLOOKUP($A10,Sheet1!$A:$AA,MATCH(B$1,Sheet1!$A$1:$AA$1,0),FALSE)=0,"",VLOOKUP($A10,Sheet1!$A:$AA,MATCH(B$1,Sheet1!$A$1:$AA$1,0),FALSE)) -> LEVITSKY DE MIGUEL, PAULA | C10: =IF(VLOOKUP($A10,Sheet1!$A:$AA,MATCH(C$1,Sheet1!$A$1:$AA$1,0),FALSE)=0,"",VLOOKUP($A10,Sheet1!$A:$AA,MATCH(C$1,Sheet1!$A$1:$AA$1,0),FALSE)) -> LEVITSKY DE MIGUEL | D10: =IF(VLOOKUP($A10,Sheet1!$A:$AA,MATCH(D$1,Sheet1!$A$1:$AA$1,0),FALSE)=0,"",VLOOKUP($A10,Sheet1!$A:$AA,MATCH(D$1,Sheet1!$A$1:$AA$1,0),FALSE)) -> PAULA | E10: =IF(VLOOKUP($A10,Sheet1!$A:$AA,MATCH(E$1,Sheet1!$A$1:$AA$1,0),FALSE)=0,"",VLOOKUP($A10,Sheet1!$A:$AA,MATCH(E$1,Sheet1!$A$1:$AA$1,0),FALSE)) | F10: =IF(VLOOKUP($A10,Sheet1!$A:$AA,MATCH(F$1,Sheet1!$A$1:$AA$1,0),FALSE)=0,"",VLOOKUP($A10,Sheet1!$A:$AA,MATCH(F$1,Sheet1!$A$1:$AA$1,0),FALSE)) | G10: =IF(VLOOKUP($A10,Sheet1!$A:$AA,MATCH(G$1,Sheet1!$A$1:$AA$1,0),FALSE)=0,"",VLOOKUP($A10,Sheet1!$A:$AA,MATCH(G$1,Sheet1!$A$1:$AA$1,0),FALSE)) | H10: =IF(VLOOKUP($A10,Sheet1!$A:$AA,MATCH(H$1,Sheet1!$A$1:$AA$1,0),FALSE)=0,"",VLOOKUP($A10,Sheet1!$A:$AA,MATCH(H$1,Sheet1!$A$1:$AA$1,0),FALSE)) | I10: =IF(VLOOKUP($A10,Sheet1!$A:$AA,MATCH(I$1,Sheet1!$A$1:$AA$1,0),FALSE)=0,"",VLOOKUP($A10,Sheet1!$A:$AA,MATCH(I$1,Sheet1!$A$1:$AA$1,0),FALSE)) | ... R10: =IF(VLOOKUP($A10,Sheet1!$A:$AA,MATCH(R$1,Sheet1!$A$1:$AA$1,0),FALSE)=0,"",VLOOKUP($A10,Sheet1!$A:$AA,MATCH(R$1,Sheet1!$A$1:$AA$1,0),FALSE)) -> 36249 | AA10: =IF(VLOOKUP($A10,Sheet1!$A:$AA,MATCH(AA$1,Sheet1!$A$1:$AA$1,0),FALSE)=0,"",VLOOKUP($A10,Sheet1!$A:$AA,MATCH(AA$1,Sheet1!$A$1:$AA$1,0),FALSE)) -> 26
A11: 9510381 | B11: =IF(VLOOKUP($A11,Sheet1!$A:$AA,MATCH(B$1,Sheet1!$A$1:$AA$1,0),FALSE)=0,"",VLOOKUP($A11,Sheet1!$A:$AA,MATCH(B$1,Sheet1!$A$1:$AA$1,0),FALSE)) -> SYROMOLOTOV NETREBIN, YURI SANTIAGO | C11: =IF(VLOOKUP($A11,Sheet1!$A:$AA,MATCH(C$1,Sheet1!$A$1:$AA$1,0),FALSE)=0,"",VLOOKUP($A11,Sheet1!$A:$AA,MATCH(C$1,Sheet1!$A$1:$AA$1,0),FALSE)) -> SYROMOLOTOV NETREBIN | D11: =IF(VLOOKUP($A11,Sheet1!$A:$AA,MATCH(D$1,Sheet1!$A$1:$AA$1,0),FALSE)=0,"",VLOOKUP($A11,Sheet1!$A:$AA,MATCH(D$1,Sheet1!$A$1:$AA$1,0),FALSE)) -> YURI SANTIAGO | E11: =IF(VLOOKUP($A11,Sheet1!$A:$AA,MATCH(E$1,Sheet1!$A$1:$AA$1,0),FALSE)=0,"",VLOOKUP($A11,Sheet1!$A:$AA,MATCH(E$1,Sheet1!$A$1:$AA$1,0),FALSE)) | F11: =IF(VLOOKUP($A11,Sheet1!$A:$AA,MATCH(F$1,Sheet1!$A$1:$AA$1,0),FALSE)=0,"",VLOOKUP($A11,Sheet1!$A:$AA,MATCH(F$1,Sheet1!$A$1:$AA$1,0),FALSE)) | G11: =IF(VLOOKUP($A11,Sheet1!$A:$AA,MATCH(G$1,Sheet1!$A$1:$AA$1,0),FALSE)=0,"",VLOOKUP($A11,Sheet1!$A:$AA,MATCH(G$1,Sheet1!$A$1:$AA$1,0),FALSE)) | H11: =IF(VLOOKUP($A11,Sheet1!$A:$AA,MATCH(H$1,Sheet1!$A$1:$AA$1,0),FALSE)=0,"",VLOOKUP($A11,Sheet1!$A:$AA,MATCH(H$1,Sheet1!$A$1:$AA$1,0),FALSE)) | I11: =IF(VLOOKUP($A11,Sheet1!$A:$AA,MATCH(I$1,Sheet1!$A$1:$AA$1,0),FALSE)=0,"",VLOOKUP($A11,Sheet1!$A:$AA,MATCH(I$1,Sheet1!$A$1:$AA$1,0),FALSE)) | ... R11: =IF(VLOOKUP($A11,Sheet1!$A:$AA,MATCH(R$1,Sheet1!$A$1:$AA$1,0),FALSE)=0,"",VLOOKUP($A11,Sheet1!$A:$AA,MATCH(R$1,Sheet1!$A$1:$AA$1,0),FALSE)) -> 35636 | AA11: =IF(VLOOKUP($A11,Sheet1!$A:$AA,MATCH(AA$1,Sheet1!$A$1:$AA$1,0),FALSE)=0,"",VLOOKUP($A11,Sheet1!$A:$AA,MATCH(AA$1,Sheet1!$A$1:$AA$1,0),FALSE)) -> 28
A12: 9563455 | B12: =IF(VLOOKUP($A12,Sheet1!$A:$AA,MATCH(B$1,Sheet1!$A$1:$AA$1,0),FALSE)=0,"",VLOOKUP($A12,Sheet1!$A:$AA,MATCH(B$1,Sheet1!$A$1:$AA$1,0),FALSE)) -> RONDON LOBATO, JOSE | C12: =IF(VLOOKUP($A12,Sheet1!$A:$AA,MATCH(C$1,Sheet1!$A$1:$AA$1,0),FALSE)=0,"",VLOOKUP($A12,Sheet1!$A:$AA,MATCH(C$1,Sheet1!$A$1:$AA$1,0),FALSE)) -> RONDON LOBATO | D12: =IF(VLOOKUP($A12,Sheet1!$A:$AA,MATCH(D$1,Sheet1!$A$1:$AA$1,0),FALSE)=0,"",VLOOKUP($A12,Sheet1!$A:$AA,MATCH(D$1,Sheet1!$A$1:$AA$1,0),FALSE)) -> JOSE | E12: =IF(VLOOKUP($A12,Sheet1!$A:$AA,MATCH(E$1,Sheet1!$A$1:$AA$1,0),FALSE)=0,"",VLOOKUP($A12,Sheet1!$A:$AA,MATCH(E$1,Sheet1!$A$1:$AA$1,0),FALSE)) | F12: =IF(VLOOKUP($A12,Sheet1!$A:$AA,MATCH(F$1,Sheet1!$A$1:$AA$1,0),FALSE)=0,"",VLOOKUP($A12,Sheet1!$A:$AA,MATCH(F$1,Sheet1!$A$1:$AA$1,0),FALSE)) | G12: =IF(VLOOKUP($A12,Sheet1!$A:$AA,MATCH(G$1,Sheet1!$A$1:$AA$1,0),FALSE)=0,"",VLOOKUP($A12,Sheet1!$A:$AA,MATCH(G$1,Sheet1!$A$1:$AA$1,0),FALSE)) | H12: =IF(VLOOKUP($A12,Sheet1!$A:$AA,MATCH(H$1,Sheet1!$A$1:$AA$1,0),FALSE)=0,"",VLOOKUP($A12,Sheet1!$A:$AA,MATCH(H$1,Sheet1!$A$1:$AA$1,0),FALSE)) | I12: =IF(VLOOKUP($A12,Sheet1!$A:$AA,MATCH(I$1,Sheet1!$A$1:$AA$1,0),FALSE)=0,"",VLOOKUP($A12,Sheet1!$A:$AA,MATCH(I$1,Sheet1!$A$1:$AA$1,0),FALSE)) | ... R12: =IF(VLOOKUP($A12,Sheet1!$A:$AA,MATCH(R$1,Sheet1!$A$1:$AA$1,0),FALSE)=0,"",VLOOKUP($A12,Sheet1!$A:$AA,MATCH(R$1,Sheet1!$A$1:$AA$1,0),FALSE)) -> 21671 | AA12: =IF(VLOOKUP($A12,Sheet1!$A:$AA,MATCH(AA$1,Sheet1!$A$1:$AA$1,0),FALSE)=0,"",VLOOKUP($A12,Sheet1!$A:$AA,MATCH(AA$1,Sheet1!$A$1:$AA$1,0),FALSE)) -> 66
A13: 9573397 | B13: =IF(VLOOKUP($A13,Sheet1!$A:$AA,MATCH(B$1,Sheet1!$A$1:$AA$1,0),FALSE)=0,"",VLOOKUP($A13,Sheet1!$A:$AA,MATCH(B$1,Sheet1!$A$1:$AA$1,0),FALSE)) -> GARCIA ALVAREZ, ALICIA | C13: =IF(VLOOKUP($A13,Sheet1!$A:$AA,MATCH(C$1,Sheet1!$A$1:$AA$1,0),FALSE)=0,"",VLOOKUP($A13,Sheet1!$A:$AA,MATCH(C$1,Sheet1!$A$1:$AA$1,0),FALSE)) -> GARCIA ALVAREZ | D13: =IF(VLOOKUP($A13,Sheet1!$A:$AA,MATCH(D$1,Sheet1!$A$1:$AA$1,0),FALSE)=0,"",VLOOKUP($A13,Sheet1!$A:$AA,MATCH(D$1,Sheet1!$A$1:$AA$1,0),FALSE)) -> ALICIA | E13: =IF(VLOOKUP($A13,Sheet1!$A:$AA,MATCH(E$1,Sheet1!$A$1:$AA$1,0),FALSE)=0,"",VLOOKUP($A13,Sheet1!$A:$AA,MATCH(E$1,Sheet1!$A$1:$AA$1,0),FALSE)) | F13: =IF(VLOOKUP($A13,Sheet1!$A:$AA,MATCH(F$1,Sheet1!$A$1:$AA$1,0),FALSE)=0,"",VLOOKUP($A13,Sheet1!$A:$AA,MATCH(F$1,Sheet1!$A$1:$AA$1,0),FALSE)) | G13: =IF(VLOOKUP($A13,Sheet1!$A:$AA,MATCH(G$1,Sheet1!$A$1:$AA$1,0),FALSE)=0,"",VLOOKUP($A13,Sheet1!$A:$AA,MATCH(G$1,Sheet1!$A$1:$AA$1,0),FALSE)) | H13: =IF(VLOOKUP($A13,Sheet1!$A:$AA,MATCH(H$1,Sheet1!$A$1:$AA$1,0),FALSE)=0,"",VLOOKUP($A13,Sheet1!$A:$AA,MATCH(H$1,Sheet1!$A$1:$AA$1,0),FALSE)) | I13: =IF(VLOOKUP($A13,Sheet1!$A:$AA,MATCH(I$1,Sheet1!$A$1:$AA$1,0),FALSE)=0,"",VLOOKUP($A13,Sheet1!$A:$AA,MATCH(I$1,Sheet1!$A$1:$AA$1,0),FALSE)) | ... R13: =IF(VLOOKUP($A13,Sheet1!$A:$AA,MATCH(R$1,Sheet1!$A$1:$AA$1,0),FALSE)=0,"",VLOOKUP($A13,Sheet1!$A:$AA,MATCH(R$1,Sheet1!$A$1:$AA$1,0),FALSE)) -> 34842 | AA13: =IF(VLOOKUP($A13,Sheet1!$A:$AA,MATCH(AA$1,Sheet1!$A$1:$AA$1,0),FALSE)=0,"",VLOOKUP($A13,Sheet1!$A:$AA,MATCH(AA$1,Sheet1!$A$1:$AA$1,0),FALSE)) -> 30
... A100: 16970437 | B100: =IF(VLOOKUP($A100,Sheet1!$A:$AA,MATCH(B$1,Sheet1!$A$1:$AA$1,0),FALSE)=0,"",VLOOKUP($A100,Sheet1!$A:$AA,MATCH(B$1,Sheet1!$A$1:$AA$1,0),FALSE)) -> Expósito, Guillermo | C100: =IF(VLOOKUP($A100,Sheet1!$A:$AA,MATCH(C$1,Sheet1!$A$1:$AA$1,0),FALSE)=0,"",VLOOKUP($A100,Sheet1!$A:$AA,MATCH(C$1,Sheet1!$A$1:$AA$1,0),FALSE)) -> Expósito | D100: =IF(VLOOKUP($A100,Sheet1!$A:$AA,MATCH(D$1,Sheet1!$A$1:$AA$1,0),FALSE)=0,"",VLOOKUP($A100,Sheet1!$A:$AA,MATCH(D$1,Sheet1!$A$1:$AA$1,0),FALSE)) -> Guillermo | E100: =IF(VLOOKUP($A100,Sheet1!$A:$AA,MATCH(E$1,Sheet1!$A$1:$AA$1,0),FALSE)=0,"",VLOOKUP($A100,Sheet1!$A:$AA,MATCH(E$1,Sheet1!$A$1:$AA$1,0),FALSE)) | F100: =IF(VLOOKUP($A100,Sheet1!$A:$AA,MATCH(F$1,Sheet1!$A$1:$AA$1,0),FALSE)=0,"",VLOOKUP($A100,Sheet1!$A:$AA,MATCH(F$1,Sheet1!$A$1:$AA$1,0),FALSE)) | G100: =IF(VLOOKUP($A100,Sheet1!$A:$AA,MATCH(G$1,Sheet1!$A$1:$AA$1,0),FALSE)=0,"",VLOOKUP($A100,Sheet1!$A:$AA,MATCH(G$1,Sheet1!$A$1:$AA$1,0),FALSE)) | H100: =IF(VLOOKUP($A100,Sheet1!$A:$AA,MATCH(H$1,Sheet1!$A$1:$AA$1,0),FALSE)=0,"",VLOOKUP($A100,Sheet1!$A:$AA,MATCH(H$1,Sheet1!$A$1:$AA$1,0),FALSE)) | I100: =IF(VLOOKUP($A100,Sheet1!$A:$AA,MATCH(I$1,Sheet1!$A$1:$AA$1,0),FALSE)=0,"",VLOOKUP($A100,Sheet1!$A:$AA,MATCH(I$1,Sheet1!$A$1:$AA$1,0),FALSE)) | ... R100: =IF(VLOOKUP($A100,Sheet1!$A:$AA,MATCH(R$1,Sheet1!$A$1:$AA$1,0),FALSE)=0,"",VLOOKUP($A100,Sheet1!$A:$AA,MATCH(R$1,Sheet1!$A$1:$AA$1,0),FALSE)) -> 01/01/1992 | AA100: =IF(VLOOKUP($A100,Sheet1!$A:$AA,MATCH(AA$1,Sheet1!$A$1:$AA$1,0),FALSE)=0,"",VLOOKUP($A100,Sheet1!$A:$AA,MATCH(AA$1,Sheet1!$A$1:$AA$1,0),FALSE)) -> 33

Sheet Ranking
A1: Licencia | B1: Puntos | C1: Apellido1 | D1: Apellido2 | E1: Nombre | F1: Ranking
A2: 6836467 | B2: 3180 | C2: Canyadell | D2: Fabregas | E2: Pep | F2: 1
A3: 6723903 | B3: 3060 | C3: De Rueda | D3: De Genover | E3: Ignasi | F3: 2
A4: 10768466 | B4: 3000 | C4: Paiva | D4: Jardim | E4: Marcello | F4: 3
A5: 10767319 | B5: 2340 | C5: Illescas | D5: Cases | E5: David | F5: 4
A6: 3039890 | B6: 1690 | C6: Martinez | D6: Santonja | E6: Esteban | F6: 5
A7: 16307820 | B7: 540 | C7: Díaz | D7: Ibáñez | E7: Sergio | F7: 6
A8: 14043335 | B8: 500 | C8: Camara | D8: Camara | E8: Pedro | F8: 7
A9: 13464954 | B9: 495 | C9: Marcos | D9: lópez | E9: Vicente | F9: 8
A10: 11855642 | B10: 335 | C10: Caymel | D10: Romero | E10: Marc | F10: 9
A11: 13005526 | B11: 250 | C11: Alvarez | D11: Escriva | E11: David | F11: 10
A12: 7404007 | B12: 180 | C12: Lopez | D12: Gomez | E12: Miguel | F12: 11
A13: 10770742 | B13: 180 | C13: Badia | D13: Carlos | F13: 12
A14: 16954449 | B14: 180 | C14: García | D14: Sánchez | E14: Mauro | F14: 13
A15: 10768565 | B15: 90 | C15: Ruiz | D15: Calvo | E15: Javier | F15: 14
A16: 10768929 | B16: 90 | C16: Vega | D16: Gutierrez | E16: Daniel | F16: 15
A17: 10768523 | B17: 90 | C17: Horcajuelo | D17: Vicente | E17: Alberto | F17: 16
A18: 16954556 | B18: 90 | C18: Campos | D18: de los Reyes | E18: Jesus | F18: 17
A19: 10768060 | B19: 45 | C19: Novales | D19: De Diago | E19: Eneko | F19: 18
A20: 4646743 | B20: 45 | C20: Corchero | D20: Ramiro | E20: Luis | F20: 19
A21: 10775403 | B21: 45 | C21: Jimenez | D21: Pueyo | E21: Constantino Adrian | F21: 20
A22: 12092433 | B22: 45 | C22: Lopez | D22: Romano | E22: Alberto | F22: 21
A23: 9425598 | B23: 45 | C23: Dóyega | D23: Rodríguez | E23: Alvaro | F23: 22
A24: 12092467 | B24: 45 | C24: Trigo | D24: Laureiro | E24: Angel Manuel | F24: 23
