Workbook

Sheet Sheet1
A1: Nº.ID | B1: Completo | C1: Apellido | D1: Nombre | E1: 2ºNombre | F1: Dirección | G1: Dirección2 | H1: Dirección3 | I1: CP | J1: Ciudad | K1: CCAA | L1: País | M1: Tfn Casa | N1: Tfn. trabajo: | O1: Móvil | P1: Email | Q1: Género | R1: F.Nac | S1: NivelIndividual | T1: NivelDobles | U1: NivelMixto | V1: Club | W1: RatingIndividual | X1: RatingDobles | Y1: RatingMixto | Z1: Admitidos | AA1: Edad
A2: 10778481 | B2: =CONCATENATE(C2,", ", D2) -> Acevedo Diaz, Victor | C2: Acevedo Diaz | D2: Victor | E2: =CONCATENATE(D2," ",C2) -> Victor Acevedo Diaz | Q2: M | R2: 30516 | AA2: =IF(ISBLANK(R2),"",((YEAR(NOW())-YEAR(R2)))) -> 41
A3: 10763937 | B3: =CONCATENATE(C3,", ", D3) -> Acuyo Osorio, Mario | C3: Acuyo Osorio | D3: Mario | E3: =CONCATENATE(D3," ",C3) -> Mario Acuyo Osorio | Q3: M | R3: 33939 | AA3: =IF(ISBLANK(R3),"",((YEAR(NOW())-YEAR(R3)))) -> 32
A4: 10771500 | B4: =CONCATENATE(C4,", ", D4) -> Adamska, Anna | C4: Adamska | D4: Anna | E4: =CONCATENATE(D4," ",C4) -> Anna Adamska | Q4: F | R4: 30909 | AA4: =IF(ISBLANK(R4),"",((YEAR(NOW())-YEAR(R4)))) -> 40
A5: 10774778 | B5: =CONCATENATE(C5,", ", D5) -> Almenar Gonzalez, Daniel | C5: Almenar Gonzalez | D5: Daniel | E5: =CONCATENATE(D5," ",C5) -> Daniel Almenar Gonzalez | Q5: M | R5: 32841 | AA5: =IF(ISBLANK(R5),"",((YEAR(NOW())-YEAR(R5)))) -> 35
A6: 13405643 | B6: =CONCATENATE(C6,", ", D6) -> Álvarez, Sara | C6: Álvarez | D6: Sara | E6: =CONCATENATE(D6," ",C6) -> Sara Álvarez | Q6: F | R6: 32011 | AA6: =IF(ISBLANK(R6),"",((YEAR(NOW())-YEAR(R6)))) -> 37
A7: 10768490 | B7: =CONCATENATE(C7,", ", D7) -> Alvarez Bolaños, Asuncion | C7: Alvarez Bolaños | D7: Asuncion | E7: =CONCATENATE(D7," ",C7) -> Asuncion Alvarez Bolaños | Q7: F | R7: 28387 | AA7: =IF(ISBLANK(R7),"",((YEAR(NOW())-YEAR(R7)))) -> 47
A8: 10134930 | B8: =CONCATENATE(C8,", ", D8) -> Alvarez Domeque, Jaime | C8: Alvarez Domeque | D8: Jaime | E8: =CONCATENATE(D8," ",C8) -> Jaime Alvarez Domeque | Q8: M | R8: 35628 | AA8: =IF(ISBLANK(R8),"",((YEAR(NOW())-YEAR(R8)))) -> 27
A9: 13005526 | B9: =CONCATENATE(C9,", ", D9) -> Alvarez Escriva, David | C9: Alvarez Escriva | D9: David | E9: =CONCATENATE(D9," ",C9) -> David Alvarez Escriva | Q9: M | R9: 36925 | AA9: =IF(ISBLANK(R9),"",((YEAR(NOW())-YEAR(R9)))) -> 23
A10: 10777615 | B10: =CONCATENATE(C10,", ", D10) -> Álvarez Iglesias, Víctor | C10: Álvarez Iglesias | D10: Víctor | E10: =CONCATENATE(D10," ",C10) -> Víctor Álvarez Iglesias | Q10: M | R10: 29797 | AA10: =IF(ISBLANK(R10),"",((YEAR(NOW())-YEAR(R10)))) -> 43
A11: 10574079 | B11: =CONCATENATE(C11,", ", D11) -> Alvarez Narros, Cristina | C11: Alvarez Narros | D11: Cristina | E11: =CONCATENATE(D11," ",C11) -> Cristina Alvarez Narros | K11: MADRID | Q11: F | U11: DX | Y11: 4.5 | AA11: =IF(ISBLANK(R11),"",((YEAR(NOW())-YEAR(R11))))
A12: 10772558 | B12: =CONCATENATE(C12,", ", D12) -> Angel Martin, Jose | C12: Angel Martin | D12: Jose | E12: =CONCATENATE(D12," ",C12) -> Jose Angel Martin | Q12: M | R12: 28324 | AA12: =IF(ISBLANK(R12),"",((YEAR(NOW())-YEAR(R12)))) -> 47
A13: 7179733 | B13: =CONCATENATE(C13,", ", D13) -> Angulo Fernández, Javier | C13: Angulo Fernández | D13: Javier | E13: =CONCATENATE(D13," ",C13) -> Javier Angulo Fernández | Q13: M | R13: 31608 | AA13: =IF(ISBLANK(R13),"",((YEAR(NOW())-YEAR(R13)))) -> 38
A14: 10768101 | B14: =CONCATENATE(C14,", ", D14) -> Ansaldo Hernandez, Pablo | C14: Ansaldo Hernandez | D14: Pablo | E14: =CONCATENATE(D14," ",C14) -> Pablo Ansaldo Hernandez | Q14: M | R14: 39792 | AA14: =IF(ISBLANK(R14),"",((YEAR(NOW())-YEAR(R14)))) -> 16
A15: T0002 | B15: =CONCATENATE(C15,", ", D15) -> Ansaldo Hernandez, Marcos | C15: Ansaldo Hernandez | D15: Marcos | E15: =CONCATENATE(D15," ",C15) -> Marcos Ansaldo Hernandez | Q15: M | AA15: =IF(ISBLANK(R15),"",((YEAR(NOW())-YEAR(R15))))
A16: 7029368 | B16: =CONCATENATE(C16,", ", D16) -> Aparicio Rivas, Enrique | C16: Aparicio Rivas | D16: Enrique | E16: =CONCATENATE(D16," ",C16) -> Enrique Aparicio Rivas | Q16: M | R16: 25861 | AA16: =IF(ISBLANK(R16),"",((YEAR(NOW())-YEAR(R16)))) -> 54
A17: T0003 | B17: =CONCATENATE(C17,", ", D17) -> Aparicio Sanchez, Enrique | C17: Aparicio Sanchez | D17: Enrique | E17: =CONCATENATE(D17," ",C17) -> Enrique Aparicio Sanchez | Q17: M | AA17: =IF(ISBLANK(R17),"",((YEAR(NOW())-YEAR(R17))))
A18: 10768581 | B18: =CONCATENATE(C18,", ", D18) -> Arias Carracedo, Maria Rosa | C18: Arias Carracedo | D18: Maria Rosa | E18: =CONCATENATE(D18," ",C18) -> Maria Rosa Arias Carracedo | Q18: F | R18: 25357 | AA18: =IF(ISBLANK(R18),"",((YEAR(NOW())-YEAR(R18)))) -> 55
A19: 16952980 | B19: =CONCATENATE(C19,", ", D19) -> Arias Gomar, Ramon | C19: Arias Gomar | D19: Ramon | E19: =CONCATENATE(D19," ",C19) -> Ramon Arias Gomar | K19: ANDALUCIA | Q19: M | S19: IM | T19: DM | W19: 5.0 | X19: 5.0 | AA19: =IF(ISBLANK(R19),"",((YEAR(NOW())-YEAR(R19))))
A20: T0061 | B20: =CONCATENATE(C20,", ", D20) -> Ariza Nuñez, Manuel | C20: Ariza Nuñez | D20: Manuel | E20: =CONCATENATE(D20," ",C20) -> Manuel Ariza Nuñez | AA20: =IF(ISBLANK(R20),"",((YEAR(NOW())-YEAR(R20))))
A21: 10770742 | B21: =CONCATENATE(C21,", ", D21) -> Badia Rambla, Carlos | C21: Badia Rambla | D21: Carlos | E21: =CONCATENATE(D21," ",C21) -> Carlos Badia Rambla | Q21: M | R21: 32230 | AA21: =IF(ISBLANK(R21),"",((YEAR(NOW())-YEAR(R21)))) -> 36
A22: T0004 | B22: =CONCATENATE(C22,", ", D22) -> Báez Clemente, Mariano | C22: Báez Clemente | D22: Mariano | E22: =CONCATENATE(D22," ",C22) -> Mariano Báez Clemente | Q22: M | AA22: =IF(ISBLANK(R22),"",((YEAR(NOW())-YEAR(R22))))
A23: 16952378 | B23: =CONCATENATE(C23,", ", D23) -> Baéz Fernández, Victor | C23: Baéz Fernández | D23: Victor | E23: =CONCATENATE(D23," ",C23) -> Victor Baéz Fernández | K23: ANDALUCIA | Q23: M | U23: DX | Y23: 4.5 | AA23: =IF(ISBLANK(R23),"",((YEAR(NOW())-YEAR(R23))))
A24: T0005 | B24: =CONCATENATE(C24,", ", D24) -> Bajo Calderón, Daniel | C24: Bajo Calderón | D24: Daniel | E24: =CONCATENATE(D24," ",C24) -> Daniel Bajo Calderón | Q24: M | AA24: =IF(ISBLANK(R24),"",((YEAR(NOW())-YEAR(R24))))
A25: 16953053 | B25: =CONCATENATE(C25,", ", D25) -> Ballesteros Aguilar, Ruben | C25: Ballesteros Aguilar | D25: Ruben | E25: =CONCATENATE(D25," ",C25) -> Ruben Ballesteros Aguilar | K25: ANDALUCIA | Q25: M | U25: DX | Y25: 4.5 | AA25: =IF(ISBLANK(R25),"",((YEAR(NOW())-YEAR(R25))))
A26: 10772920 | B26: =CONCATENATE(C26,", ", D26) -> Barbero, Lorena | C26: Barbero | D26: Lorena | E26: =CONCATENATE(D26," ",C26) -> Lorena Barbero | Q26: F | R26: 30285 | AA26: =IF(ISBLANK(R26),"",((YEAR(NOW())-YEAR(R26)))) -> 42
A27: 10778837 | B27: =CONCATENATE(C27,", ", D27) -> Barbero, Jose | C27: Barbero | D27: Jose | E27: =CONCATENATE(D27," ",C27) -> Jose Barbero | Q27: M | R27: 26726 | AA27: =IF(ISBLANK(R27),"",((YEAR(NOW())-YEAR(R27)))) -> 51
A28: T0006 | B28: =CONCATENATE(C28,", ", D28) -> Baudet Vera, Rafael | C28: Baudet Vera | D28: Rafael | E28: =CONCATENATE(D28," ",C28) -> Rafael Baudet Vera | Q28: M | AA28: =IF(ISBLANK(R28),"",((YEAR(NOW())-YEAR(R28))))
A29: 5819521 | B29: =CONCATENATE(C29,", ", D29) -> Beltran Molina, Julia | C29: Beltran Molina | D29: Julia | E29: =CONCATENATE(D29," ",C29) -> Julia Beltran Molina | Q29: F | R29: 34548 | AA29: =IF(ISBLANK(R29),"",((YEAR(NOW())-YEAR(R29)))) -> 30
A30: 10765602 | B30: =CONCATENATE(C30,", ", D30) -> Benito Ludeña, José Luis | C30: Benito Ludeña | D30: José Luis | E30: =CONCATENATE(D30," ",C30) -> José Luis Benito Ludeña | Q30: M | R30: 22083 | AA30: =IF(ISBLANK(R30),"",((YEAR(NOW())-YEAR(R30)))) -> 64
A31: 10110146 | B31: =CONCATENATE(C31,", ", D31) -> Bergareche Sans, Borja | C31: Bergareche Sans | D31: Borja | E31: =CONCATENATE(D31," ",C31) -> Borja Bergareche Sans | Q31: M | R31: 31037 | AA31: =IF(ISBLANK(R31),"",((YEAR(NOW())-YEAR(R31)))) -> 40
A32: 10602250 | B32: =CONCATENATE(C32,", ", D32) -> Bermudo Mera, Juan | C32: Bermudo Mera | D32: Juan | E32: =CONCATENATE(D32," ",C32) -> Juan Bermudo Mera | Q32: M | R32: 34134 | AA32: =IF(ISBLANK(R32),"",((YEAR(NOW())-YEAR(R32)))) -> 31
A33: 10574095 | B33: =CONCATENATE(C33,", ", D33) -> Bilbao Areitio, Beatriz | C33: Bilbao Areitio | D33: Beatriz | E33: =CONCATENATE(D33," ",C33) -> Beatriz Bilbao Areitio | Q33: F | R33: 35388 | AA33: =IF(ISBLANK(R33),"",((YEAR(NOW())-YEAR(R33)))) -> 28
A34: 10767418 | B34: =CONCATENATE(C34,", ", D34) -> Bitaine , Alex | C34: Bitaine | D34: Alex | E34: =CONCATENATE(D34," ",C34) -> Alex Bitaine | K34: MADRID | Q34: F | S34: IF | T34: DF | U34: DX | W34: 4.5 | X34: 4.5 | Y34: 4.5 | AA34: =IF(ISBLANK(R34),"",((YEAR(NOW())-YEAR(R34))))
A35: 10081610 | B35: =CONCATENATE(C35,", ", D35) -> Bitan Georget, Federico | C35: Bitan Georget | D35: Federico | E35: =CONCATENATE(D35," ",C35) -> Federico Bitan Georget | Q35: M | R35: 25791 | AA35: =IF(ISBLANK(R35),"",((YEAR(NOW())-YEAR(R35)))) -> 54
A36: 10765983 | B36: =CONCATENATE(C36,", ", D36) -> Blanco Acedo, Francisco Javier | C36: Blanco Acedo | D36: Francisco Javier | E36: =CONCATENATE(D36," ",C36) -> Francisco Javier Blanco Acedo | K36: MADRID | Q36: M | U36: DX | Y36: 4.5 | AA36: =IF(ISBLANK(R36),"",((YEAR(NOW())-YEAR(R36))))
A37: 16952906 | B37: =CONCATENATE(C37,", ", D37) -> Blanco Assanelli, Vanesa Noelia | C37: Blanco Assanelli | D37: Vanesa Noelia | E37: =CONCATENATE(D37," ",C37) -> Vanesa Noelia Blanco Assanelli | K37: ANDALUCIA | Q37: F | T37: DF | U37: DX | X37: 4.5 | Y37: 4.5 | AA37: =IF(ISBLANK(R37),"",((YEAR(NOW())-YEAR(R37))))
A38: 10771237 | B38: =CONCATENATE(C38,", ", D38) -> Bravo Muro, Raul | C38: Bravo Muro | D38: Raul | E38: =CONCATENATE(D38," ",C38) -> Raul Bravo Muro | Q38: M | R38: 28688 | AA38: =IF(ISBLANK(R38),"",((YEAR(NOW())-YEAR(R38)))) -> 46
A39: 10773150 | B39: =CONCATENATE(C39,", ", D39) -> Bueno, Marisa | C39: Bueno | D39: Marisa | E39: =CONCATENATE(D39," ",C39) -> Marisa Bueno | Q39: F | R39: 25515 | AA39: =IF(ISBLANK(R39),"",((YEAR(NOW())-YEAR(R39)))) -> 55
A40: 10640755 | B40: =CONCATENATE(C40,", ", D40) -> Calvo Lopez, Valeria | C40: Calvo Lopez | D40: Valeria | E40: =CONCATENATE(D40," ",C40) -> Valeria Calvo Lopez | Q40: F | R40: 41241 | AA40: =IF(ISBLANK(R40),"",((YEAR(NOW())-YEAR(R40)))) -> 12
...

Sheet Master Final Madrid 2024
A1: Nº.ID | B1: Completo | C1: Apellido | D1: Nombre | E1: 2ºNombre | F1: Dirección | G1: Dirección2 | H1: Dirección3 | I1: CP | J1: Ciudad | K1: CCAA | L1: País | M1: Tfn Casa | N1: Tfn. trabajo: | O1: Móvil | P1: Email | Q1: Género | R1: F.Nac | S1: NivelIndividual | T1: NivelDobles | U1: NivelMixto | V1: Club | W1: RatingIndividual | X1: RatingDobles | Y1: RatingMixto | Z1: Admitidos | AA1: Edad
A2: 10768466 | B2: Paiva Jardim, Marcello | C2: Paiva Jardim | D2: Marcello | E2: Marcello Paiva Jardim | K2: MADRID | Q2: M | S2: IM | T2: DM | U2: DX | W2: 5.0 | X2: 5.0 | Y2: 5.0
A3: 10767319 | B3: Illescas Cases, David | C3: Illescas Cases | D3: David | E3: David Illescas Cases | K3: MADRID | Q3: M | S3: IM | T3: DM | U3: DX | W3: 5.0 | X3: 5.0 | Y3: 5.0
A4: 6836467 | B4: Canyadell Fabregas, Pep | C4: Canyadell Fabregas | D4: Pep | E4: Pep Canyadell Fabregas | K4: CATALUÑA | Q4: M | S4: IM | T4: DM | U4: DX | W4: 5.0 | X4: 5.0 | Y4: 5.0
A5: 16952360 | B5: Casquero Herrero, Antonio | C5: Casquero Herrero | D5: Antonio | E5: Antonio Casquero Herrero | K5: ANDALUCIA | Q5: M | S5: IM | T5: DM | W5: 5.0 | X5: 5.0
A6: 13464954 | B6: Marcos López, Vicente | C6: Marcos López | D6: Vicente | E6: Vicente Marcos López | K6: C. VALENCIA | Q6: M | S6: IM | T6: DM | U6: DX | W6: 5.0 | X6: 5.0 | Y6: 5.0
A7: 16307820 | B7: Díaz Ibáñez, Sergio | C7: Díaz Ibáñez | D7: Sergio | E7: Sergio Díaz Ibáñez | K7: CEUTA | Q7: M | R7: 34517 | S7: IM | T7: DM | W7: 5.0 | X7: 5.0 | AA7: 30
A8: 16952980 | B8: Arias Gomar, Ramon | C8: Arias Gomar | D8: Ramon | E8: Ramon Arias Gomar | K8: ANDALUCIA | Q8: M | S8: IM | T8: DM | W8: 5.0 | X8: 5.0
A9: 6723903 | B9: De Rueda De Genover, Ignasi | C9: De Rueda De Genover | D9: Ignasi | E9: Ignasi De Rueda De Genover | K9: CATALUÑA | Q9: M | S9: IM | T9: DM | U9: DX | W9: 5.0 | X9: 5.0 | Y9: 5.0
A10: 16937065 | B10: Pereira de Mattos, Domini Elias | C10: Pereira de Mattos | D10: Domini Elias | E10: Domini Elias Pereira de Mattos | K10: ANDALUCIA | Q10: M | S10: IM | T10: DM | U10: DX | W10: 5.0 | X10: 5.0 | Y10: 5.0
A11: 11855642 | B11: Caymel Romero, Marc | C11: Caymel Romero | D11: Marc | E11: Marc Caymel Romero | K11: CATALUÑA | Q11: M | S11: IM | T11: DM | U11: DX | W11: 5.0 | X11: 5.0 | Y11: 5.0
A12: 10768565 | B12: Ruiz Calvo, Javier | C12: Ruiz Calvo | D12: Javier | E12: Javier Ruiz Calvo | K12: MADRID | Q12: M | R12: 30209 | S12: IM | T12: DM | U12: DX | W12: 5.0 | X12: 5.0 | Y12: 5.0 | AA12: 42
A13: 10768929 | B13: Vega Gutierrez, Daniel | C13: Vega Gutierrez | D13: Daniel | E13: Daniel Vega Gutierrez | K13: MADRID | Q13: M | S13: IM | T13: DM | W13: 5.0
A14: 13465308 | B14: Lillo Pellies, Sergio | C14: Lillo Pellies | D14: Sergio | E14: Sergio Lillo Pellies | K14: C. VALENCIA | Q14: M | S14: IM | T14: DM | W14: 5.0 | X14: 5.0
A15: 10768523 | B15: Horcajuelo Vicente, Alberto | C15: Horcajuelo Vicente | D15: Alberto | E15: Alberto Horcajuelo Vicente | K15: MADRID | Q15: M | S15: IM | T15: DM | W15: 5.0 | X15: 5.0
A16: 7404007 | B16: Lopez Gomez, Miguel | C16: Lopez Gomez | D16: Miguel | E16: Miguel Lopez Gomez | K16: MADRID | Q16: M | R16: 34605 | S16: IM | T16: DM | U16: DX | W16: 5.0 | X16: 5.0 | Y16: 4.5 | AA16: 30
A17: 3039890 | B17: Martinez Santonja, Esteban | C17: Martinez Santonja | D17: Esteban | E17: Esteban Martinez Santonja | K17: C. VALENCIA | Q17: M | S17: IM | T17: DM | W17: 5.0 | X17: 5.0
A18: 7238183 | B18: Mendez Dominguez, Sabrina | C18: Mendez Dominguez | D18: Sabrina | E18: Sabrina Mendez Dominguez | K18: MADRID | Q18: F | S18: IF | T18: DF | U18: DX | W18: 5.0 | X18: 5.0 | Y18: 5.0
A19: 10769042 | B19: Derbis , Nerea | C19: Derbis | D19: Nerea | E19: Nerea Derbis | K19: MADRID | Q19: F | S19: IF | T19: DF | U19: DX | W19: 5.0 | X19: 5.0 | Y19: 5.0
A20: 8318942 | B20: Chumillas Lidón, Sara | C20: Chumillas Lidón | D20: Sara | E20: Sara Chumillas Lidón | K20: MADRID | Q20: F | S20: IF | T20: DF | U20: DX | W20: 5.0 | X20: 5.0 | Y20: 5.0
A21: 10768911 | B21: Cardo Rodriguez, Rocio | C21: Cardo Rodriguez | D21: Rocio | E21: Rocio Cardo Rodriguez | K21: MADRID | Q21: F | R21: 32449 | S21: IF | T21: DF | U21: DX | W21: 5.0 | X21: 5.0 | Y21: 5.0 | AA21: 36
A22: 11855501 | B22: Caymel Romero, Claudia | C22: Caymel Romero | D22: Claudia | E22: Claudia Caymel Romero | K22: CATALUÑA | Q22: F | S22: IF | T22: DF | U22: DX | W22: 5.0 | X22: 5.0 | Y22: 5.0
A23: 10768078 | B23: Vazquez Ranz, Karina | C23: Vazquez Ranz | D23: Karina | E23: Karina Vazquez Ranz | K23: MADRID | Q23: F | S23: IF | T23: DF | U23: DX | W23: 5.0 | Y23: 5.0
A24: 9573397 | B24: García Álvarez, Alicia | C24: García Álvarez | D24: Alicia | E24: Alicia García Álvarez | K24: ANDALUCIA | Q24: F | S24: IF | T24: DF | U24: DX | W24: 4.5 | X24: 4.5 | Y24: 4.5
A25: 16951726 | B25: Millon Soto, Celia | C25: Millon Soto | D25: Celia | E25: Celia Millon Soto | K25: ANDALUCIA | Q25: F | S25: IF | T25: DF | U25: DX | W25: 4.5 | X25: 4.5 | Y25: 4.5
A26: 11855163 | B26: Serrano Lopez, Katherine Vanessa | C26: Serrano Lopez | D26: Katherine Vanessa | E26: Katherine Vanessa Serrano Lopez | K26: CATALUÑA | Q26: F | S26: IF | T26: DF | U26: DX | W26: 4.5 | X26: 4.5 | Y26: 4.5
A27: 10768804 | B27: De Miguel Gonzalez, Maria | C27: De Miguel Gonzalez | D27: Maria | E27: Maria De Miguel Gonzalez | K27: MADRID | Q27: F | R27: 31433 | S27: IF | T27: DF | W27: 4.5 | AA27: 38
A28: 10767418 | B28: Bitaine , Alex | C28: Bitaine | D28: Alex | E28: Alex Bitaine | K28: MADRID | Q28: F | S28: IF | T28: DF | U28: DX | W28: 4.5 | X28: 4.5 | Y28: 4.5
A29: 10058320 | B29: Cartagena, Carlota | C29: Cartagena | D29: Carlota | E29: Carlota Cartagena | K29: MADRID | Q29: F | R29: 35899 | S29: IF | T29: DF | W29: 4.5 | AA29: 26
A30: 10767161 | B30: Fierro Gonzalez, Monica | C30: Fierro Gonzalez | D30: Monica | E30: Monica Fierro Gonzalez | K30: MADRID | Q30: F | U30: DX | Y30: 4.5
A31: 16953045 | B31: Varo Martínez, Vanessa | C31: Varo Martínez | D31: Vanessa | E31: Vanessa Varo Martínez | K31: ANDALUCIA | Q31: F | S31: IF | T31: DF | U31: DX | W31: 4.5 | X31: 4.5 | Y31: 4.5
A32: 11087344 | B32: Dominguez Luna, Sheila | C32: Dominguez Luna | D32: Sheila | E32: Sheila Dominguez Luna | K32: CATALUÑA | Q32: F | S32: IF | W32: 3.5
A33: 11855626 | B33: Castells Carbonell, Anna | C33: Castells Carbonell | D33: Anna | E33: Anna Castells Carbonell | K33: CATALUÑA | Q33: F | S33: IF | T33: DF | W33: 3.5
A34: 11856046 | B34: Ferrer Ramon, Marta | C34: Ferrer Ramon | D34: Marta | E34: Marta Ferrer Ramon | K34: CATALUÑA | Q34: F | S34: IF | T34: DF | W34: 3.5
A35: 11855288 | B35: Hernández , Laura | C35: Hernández | D35: Laura | E35: Laura Hernández | K35: CATALUÑA | Q35: F | S35: IF | T35: DF | W35: 3.5
A36: 16953342 | B36: Gallego Ruiz-Mateos, Javier | C36: Gallego Ruiz-Mateos | D36: Javier | E36: Javier Gallego Ruiz-Mateos | K36: ANDALUCIA | Q36: M | S36: IM | T36: DM | U36: DX | W36: 5.0 | X36: 5.0 | Y36: 5.0
A37: 10768961 | B37: Prieto Perez, Álvaro | C37: Prieto Perez | D37: Álvaro | E37: Álvaro Prieto Perez | K37: MADRID | Q37: M | R37: 29946 | S37: IM | T37: DM | U37: DX | W37: 5.0 | X37: 5.0 | Y37: 5.0 | AA37: 43
A38: 10768185 | B38: Cardenas Santa, Ernesto | C38: Cardenas Santa | D38: Ernesto | E38: Ernesto Cardenas Santa | Q38: M | S38: IM | T38: DM | U38: DX | W38: 5.0 | X38: 5.0 | Y38: 5.0
A39: 10767103 | B39: Perez Soto, Carlos Alberto | C39: Perez Soto | D39: Carlos Alberto | E39: Carlos Alberto Perez Soto | K39: MADRID | Q39: M | R39: 28564 | S39: IM | T39: DM | U39: DX | W39: 5.0 | X39: 5.0 | Y39: 5.0 | AA39: 46
A40: 16913578 | B40: Serrano Ruano, Alexander | C40: Serrano Ruano | D40: Alexander | E40: Alexander Serrano Ruano | Q40: M | S40: IM | T40: DM | W40: 5.0 | X40: 5.0
...

Sheet FORMULAS
A1: Nº.ID | B1: Completo | C1: Apellido | D1: Nombre | E1: 2ºNombre | F1: Dirección | G1: Dirección2 | H1: Dirección3 | I1: CP | J1: Ciudad | K1: CCAA | L1: País | M1: Tfn Casa | N1: Tfn. trabajo: | O1: Móvil | P1: Email | Q1: Género | R1: F.Nac | S1: NivelIndividual | T1: NivelDobles | U1: NivelMixto | V1: Club | W1: RatingIndividual | X1: RatingDobles | Y1: RatingMixto | Z1: Admitidos | AA1: Edad
A2: 10768466 | B2: =IF(VLOOKUP($A2,Sheet1!$A:$AA,MATCH(B$1,Sheet1!$A$1:$AA$1,0),FALSE)=0,"",VLOOKUP($A2,Sheet1!$A:$AA,MATCH(B$1,Sheet1!$A$1:$AA$1,0),FALSE)) -> Paiva Jardim, Marcello | C2: =IF(VLOOKUP($A2,Sheet1!$A:$AA,MATCH(C$1,Sheet1!$A$1:$AA$1,0),FALSE)=0,"",VLOOKUP($A2,Sheet1!$A:$AA,MATCH(C$1,Sheet1!$A$1:$AA$1,0),FALSE)) -> Paiva Jardim | D2: =IF(VLOOKUP($A2,Sheet1!$A:$AA,MATCH(D$1,Sheet1!$A$1:$AA$1,0),FALSE)=0,"",VLOOKUP($A2,Sheet1!$A:$AA,MATCH(D$1,Sheet1!$A$1:$AA$1,0),FALSE)) -> Marcello | E2: =IF(VLOOKUP($A2,Sheet1!$A:$AA,MATCH(E$1,Sheet1!$A$1:$AA$1,0),FALSE)=0,"",VLOOKUP($A2,Sheet1!$A:$AA,MATCH(E$1,Sheet1!$A$1:$AA$1,0),FALSE)) -> Marcello Paiva Jardim | F2: =IF(VLOOKUP($A2,Sheet1!$A:$AA,MATCH(F$1,Sheet1!$A$1:$AA$1,0),FALSE)=0,"",VLOOKUP($A2,Sheet1!$A:$AA,MATCH(F$1,Sheet1!$A$1:$AA$1,0),FALSE)) | G2: =IF(VLOOKUP($A2,Sheet1!$A:$AA,MATCH(G$1,Sheet1!$A$1:$AA$1,0),FALSE)=0,"",VLOOKUP($A2,Sheet1!$A:$AA,MATCH(G$1,Sheet1!$A$1:$AA$1,0),FALSE)) | H2: =IF(VLOOKUP($A2,Sheet1!$A:$AA,MATCH(H$1,Sheet1!$A$1:$AA$1,0),FALSE)=0,"",VLOOKUP($A2,Sheet1!$A:$AA,MATCH(H$1,Sheet1!$A$1:$AA$1,0),FALSE)) | I2: =IF(VLOOKUP($A2,Sheet1!$A:$AA,MATCH(I$1,Sheet1!$A$1:$AA$1,0),FALSE)=0,"",VLOOKUP($A2,Sheet1!$A:$AA,MATCH(I$1,Sheet1!$A$1:$AA$1,0),FALSE)) | ... AA2: =IF(VLOOKUP($A2,Sheet1!$A:$AA,MATCH(AA$1,Sheet1!$A$1:$AA$1,0),FALSE)=0,"",VLOOKUP($A2,Sheet1!$A:$AA,MATCH(AA$1,Sheet1!$A$1:$AA$1,0),FALSE))
A3: 10767319 | B3: =IF(VLOOKUP($A3,Sheet1!$A:$AA,MATCH(B$1,Sheet1!$A$1:$AA$1,0),FALSE)=0,"",VLOOKUP($A3,Sheet1!$A:$AA,MATCH(B$1,Sheet1!$A$1:$AA$1,0),FALSE)) -> Illescas Cases, David | C3: =IF(VLOOKUP($A3,Sheet1!$A:$AA,MATCH(C$1,Sheet1!$A$1:$AA$1,0),FALSE)=0,"",VLOOKUP($A3,Sheet1!$A:$AA,MATCH(C$1,Sheet1!$A$1:$AA$1,0),FALSE)) -> Illescas Cases | D3: =IF(VLOOKUP($A3,Sheet1!$A:$AA,MATCH(D$1,Sheet1!$A$1:$AA$1,0),FALSE)=0,"",VLOOKUP($A3,Sheet1!$A:$AA,MATCH(D$1,Sheet1!$A$1:$AA$1,0),FALSE)) -> David | E3: =IF(VLOOKUP($A3,Sheet1!$A:$AA,MATCH(E$1,Sheet1!$A$1:$AA$1,0),FALSE)=0,"",VLOOKUP($A3,Sheet1!$A:$AA,MATCH(E$1,Sheet1!$A$1:$AA$1,0),FALSE)) -> David Illescas Cases | F3: =IF(VLOOKUP($A3,Sheet1!$A:$AA,MATCH(F$1,Sheet1!$A$1:$AA$1,0),FALSE)=0,"",VLOOKUP($A3,Sheet1!$A:$AA,MATCH(F$1,Sheet1!$A$1:$AA$1,0),FALSE)) | G3: =IF(VLOOKUP($A3,Sheet1!$A:$AA,MATCH(G$1,Sheet1!$A$1:$AA$1,0),FALSE)=0,"",VLOOKUP($A3,Sheet1!$A:$AA,MATCH(G$1,Sheet1!$A$1:$AA$1,0),FALSE)) | H3: =IF(VLOOKUP($A3,Sheet1!$A:$AA,MATCH(H$1,Sheet1!$A$1:$AA$1,0),FALSE)=0,"",VLOOKUP($A3,Sheet1!$A:$AA,MATCH(H$1,Sheet1!$A$1:$AA$1,0),FALSE)) | I3: =IF(VLOOKUP($A3,Sheet1!$A:$AA,MATCH(I$1,Sheet1!$A$1:$AA$1,0),FALSE)=0,"",VLOOKUP($A3,Sheet1!$A:$AA,MATCH(I$1,Sheet1!$A$1:$AA$1,0),FALSE)) | ... AA3: =IF(VLOOKUP($A3,Sheet1!$A:$AA,MATCH(AA$1,Sheet1!$A$1:$AA$1,0),FALSE)=0,"",VLOOKUP($A3,Sheet1!$A:$AA,MATCH(AA$1,Sheet1!$A$1:$AA$1,0),FALSE))
A4: 6836467 | B4: =IF(VLOOKUP($A4,Sheet1!$A:$AA,MATCH(B$1,Sheet1!$A$1:$AA$1,0),FALSE)=0,"",VLOOKUP($A4,Sheet1!$A:$AA,MATCH(B$1,Sheet1!$A$1:$AA$1,0),FALSE)) -> Canyadell Fabregas, Pep | C4: =IF(VLOOKUP($A4,Sheet1!$A:$AA,MATCH(C$1,Sheet1!$A$1:$AA$1,0),FALSE)=0,"",VLOOKUP($A4,Sheet1!$A:$AA,MATCH(C$1,Sheet1!$A$1:$AA$1,0),FALSE)) -> Canyadell Fabregas | D4: =IF(VLOOKUP($A4,Sheet1!$A:$AA,MATCH(D$1,Sheet1!$A$1:$AA$1,0),FALSE)=0,"",VLOOKUP($A4,Sheet1!$A:$AA,MATCH(D$1,Sheet1!$A$1:$AA$1,0),FALSE)) -> Pep | E4: =IF(VLOOKUP($A4,Sheet1!$A:$AA,MATCH(E$1,Sheet1!$A$1:$AA$1,0),FALSE)=0,"",VLOOKUP($A4,Sheet1!$A:$AA,MATCH(E$1,Sheet1!$A$1:$AA$1,0),FALSE)) -> Pep Canyadell Fabregas | F4: =IF(VLOOKUP($A4,Sheet1!$A:$AA,MATCH(F$1,Sheet1!$A$1:$AA$1,0),FALSE)=0,"",VLOOKUP($A4,Sheet1!$A:$AA,MATCH(F$1,Sheet1!$A$1:$AA$1,0),FALSE)) | G4: =IF(VLOOKUP($A4,Sheet1!$A:$AA,MATCH(G$1,Sheet1!$A$1:$AA$1,0),FALSE)=0,"",VLOOKUP($A4,Sheet1!$A:$AA,MATCH(G$1,Sheet1!$A$1:$AA$1,0),FALSE)) | H4: =IF(VLOOKUP($A4,Sheet1!$A:$AA,MATCH(H$1,Sheet1!$A$1:$AA$1,0),FALSE)=0,"",VLOOKUP($A4,Sheet1!$A:$AA,MATCH(H$1,Sheet1!$A$1:$AA$1,0),FALSE)) | I4: =IF(VLOOKUP($A4,Sheet1!$A:$AA,MATCH(I$1,Sheet1!$A$1:$AA$1,0),FALSE)=0,"",VLOOKUP($A4,Sheet1!$A:$AA,MATCH(I$1,Sheet1!$A$1:$AA$1,0),FALSE)) | ... AA4: =IF(VLOOKUP($A4,Sheet1!$A:$AA,MATCH(AA$1,Sheet1!$A$1:$AA$1,0),FALSE)=0,"",VLOOKUP($A4,Sheet1!$A:$AA,MATCH(AA$1,Sheet1!$A$1:$AA$1,0),FALSE))
A5: 16952360 | B5: =IF(VLOOKUP($A5,Sheet1!$A:$AA,MATCH(B$1,Sheet1!$A$1:$AA$1,0),FALSE)=0,"",VLOOKUP($A5,Sheet1!$A:$AA,MATCH(B$1,Sheet1!$A$1:$AA$1,0),FALSE)) -> Casquero Herrero, Antonio | C5: =IF(VLOOKUP($A5,Sheet1!$A:$AA,MATCH(C$1,Sheet1!$A$1:$AA$1,0),FALSE)=0,"",VLOOKUP($A5,Sheet1!$A:$AA,MATCH(C$1,Sheet1!$A$1:$AA$1,0),FALSE)) -> Casquero Herrero | D5: =IF(VLOOKUP($A5,Sheet1!$A:$AA,MATCH(D$1,Sheet1!$A$1:$AA$1,0),FALSE)=0,"",VLOOKUP($A5,Sheet1!$A:$AA,MATCH(D$1,Sheet1!$A$1:$AA$1,0),FALSE)) -> Antonio | E5: =IF(VLOOKUP($A5,Sheet1!$A:$AA,MATCH(E$1,Sheet1!$A$1:$AA$1,0),FALSE)=0,"",VLOOKUP($A5,Sheet1!$A:$AA,MATCH(E$1,Sheet1!$A$1:$AA$1,0),FALSE)) -> Antonio Casquero Herrero | F5: =IF(VLOOKUP($A5,Sheet1!$A:$AA,MATCH(F$1,Sheet1!$A$1:$AA$1,0),FALSE)=0,"",VLOOKUP($A5,Sheet1!$A:$AA,MATCH(F$1,Sheet1!$A$1:$AA$1,0),FALSE)) | G5: =IF(VLOOKUP($A5,Sheet1!$A:$AA,MATCH(G$1,Sheet1!$A$1:$AA$1,0),FALSE)=0,"",VLOOKUP($A5,Sheet1!$A:$AA,MATCH(G$1,Sheet1!$A$1:$AA$1,0),FALSE)) | H5: =IF(VLOOKUP($A5,Sheet1!$A:$AA,MATCH(H$1,Sheet1!$A$1:$AA$1,0),FALSE)=0,"",VLOOKUP($A5,Sheet1!$A:$AA,MATCH(H$1,Sheet1!$A$1:$AA$1,0),FALSE)) | I5: =IF(VLOOKUP($A5,Sheet1!$A:$AA,MATCH(I$1,Sheet1!$A$1:$AA$1,0),FALSE)=0,"",VLOOKUP($A5,Sheet1!$A:$AA,MATCH(I$1,Sheet1!$A$1:$AA$1,0),FALSE)) | ... AA5: =IF(VLOOKUP($A5,Sheet1!$A:$AA,MATCH(AA$1,Sheet1!$A$1:$AA$1,0),FALSE)=0,"",VLOOKUP($A5,Sheet1!$A:$AA,MATCH(AA$1,Sheet1!$A$1:$AA$1,0),FALSE))
A6: 13464954 | B6: =IF(VLOOKUP($A6,Sheet1!$A:$AA,MATCH(B$1,Sheet1!$A$1:$AA$1,0),FALSE)=0,"",VLOOKUP($A6,Sheet1!$A:$AA,MATCH(B$1,Sheet1!$A$1:$AA$1,0),FALSE)) -> Marcos López, Vicente | C6: =IF(VLOOKUP($A6,Sheet1!$A:$AA,MATCH(C$1,Sheet1!$A$1:$AA$1,0),FALSE)=0,"",VLOOKUP($A6,Sheet1!$A:$AA,MATCH(C$1,Sheet1!$A$1:$AA$1,0),FALSE)) -> Marcos López | D6: =IF(VLOOKUP($A6,Sheet1!$A:$AA,MATCH(D$1,Sheet1!$A$1:$AA$1,0),FALSE)=0,"",VLOOKUP($A6,Sheet1!$A:$AA,MATCH(D$1,Sheet1!$A$1:$AA$1,0),FALSE)) -> Vicente | E6: =IF(VLOOKUP($A6,Sheet1!$A:$AA,MATCH(E$1,Sheet1!$A$1:$AA$1,0),FALSE)=0,"",VLOOKUP($A6,Sheet1!$A:$AA,MATCH(E$1,Sheet1!$A$1:$AA$1,0),FALSE)) -> Vicente Marcos López | F6: =IF(VLOOKUP($A6,Sheet1!$A:$AA,MATCH(F$1,Sheet1!$A$1:$AA$1,0),FALSE)=0,"",VLOOKUP($A6,Sheet1!$A:$AA,MATCH(F$1,Sheet1!$A$1:$AA$1,0),FALSE)) | G6: =IF(VLOOKUP($A6,Sheet1!$A:$AA,MATCH(G$1,Sheet1!$A$1:$AA$1,0),FALSE)=0,"",VLOOKUP($A6,Sheet1!$A:$AA,MATCH(G$1,Sheet1!$A$1:$AA$1,0),FALSE)) | H6: =IF(VLOOKUP($A6,Sheet1!$A:$AA,MATCH(H$1,Sheet1!$A$1:$AA$1,0),FALSE)=0,"",VLOOKUP($A6,Sheet1!$A:$AA,MATCH(H$1,Sheet1!$A$1:$AA$1,0),FALSE)) | I6: =IF(VLOOKUP($A6,Sheet1!$A:$AA,MATCH(I$1,Sheet1!$A$1:$AA$1,0),FALSE)=0,"",VLOOKUP($A6,Sheet1!$A:$AA,MATCH(I$1,Sheet1!$A$1:$AA$1,0),FALSE)) | ... AA6: =IF(VLOOKUP($A6,Sheet1!$A:$AA,MATCH(AA$1,Sheet1!$A$1:$AA$1,0),FALSE)=0,"",VLOOKUP($A6,Sheet1!$A:$AA,MATCH(AA$1,Sheet1!$A$1:$AA$1,0),FALSE))
A7: 16307820 | B7: =IF(VLOOKUP($A7,Sheet1!$A:$AA,MATCH(B$1,Sheet1!$A$1:$AA$1,0),FALSE)=0,"",VLOOKUP($A7,Sheet1!$A:$AA,MATCH(B$1,Sheet1!$A$1:$AA$1,0),FALSE)) -> Díaz Ibáñez, Sergio | C7: =IF(VLOOKUP($A7,Sheet1!$A:$AA,MATCH(C$1,Sheet1!$A$1:$AA$1,0),FALSE)=0,"",VLOOKUP($A7,Sheet1!$A:$AA,MATCH(C$1,Sheet1!$A$1:$AA$1,0),FALSE)) -> Díaz Ibáñez | D7: =IF(VLOOKUP($A7,Sheet1!$A:$AA,MATCH(D$1,Sheet1!$A$1:$AA$1,0),FALSE)=0,"",VLOOKUP($A7,Sheet1!$A:$AA,MATCH(D$1,Sheet1!$A$1:$AA$1,0),FALSE)) -> Sergio | E7: =IF(VLOOKUP($A7,Sheet1!$A:$AA,MATCH(E$1,Sheet1!$A$1:$AA$1,0),FALSE)=0,"",VLOOKUP($A7,Sheet1!$A:$AA,MATCH(E$1,Sheet1!$A$1:$AA$1,0),FALSE)) -> Sergio Díaz Ibáñez | F7: =IF(VLOOKUP($A7,Sheet1!$A:$AA,MATCH(F$1,Sheet1!$A$1:$AA$1,0),FALSE)=0,"",VLOOKUP($A7,Sheet1!$A:$AA,MATCH(F$1,Sheet1!$A$1:$AA$1,0),FALSE)) | G7: =IF(VLOOKUP($A7,Sheet1!$A:$AA,MATCH(G$1,Sheet1!$A$1:$AA$1,0),FALSE)=0,"",VLOOKUP($A7,Sheet1!$A:$AA,MATCH(G$1,Sheet1!$A$1:$AA$1,0),FALSE)) | H7: =IF(VLOOKUP($A7,Sheet1!$A:$AA,MATCH(H$1,Sheet1!$A$1:$AA$1,0),FALSE)=0,"",VLOOKUP($A7,Sheet1!$A:$AA,MATCH(H$1,Sheet1!$A$1:$AA$1,0),FALSE)) | I7: =IF(VLOOKUP($A7,Sheet1!$A:$AA,MATCH(I$1,Sheet1!$A$1:$AA$1,0),FALSE)=0,"",VLOOKUP($A7,Sheet1!$A:$AA,MATCH(I$1,Sheet1!$A$1:$AA$1,0),FALSE)) | ... AA7: =IF(VLOOKUP($A7,Sheet1!$A:$AA,MATCH(AA$1,Sheet1!$A$1:$AA$1,0),FALSE)=0,"",VLOOKUP($A7,Sheet1!$A:$AA,MATCH(AA$1,Sheet1!$A$1:$AA$1,0),FALSE)) -> 30
A8: 16952980 | B8: =IF(VLOOKUP($A8,Sheet1!$A:$AA,MATCH(B$1,Sheet1!$A$1:$AA$1,0),FALSE)=0,"",VLOOKUP($A8,Sheet1!$A:$AA,MATCH(B$1,Sheet1!$A$1:$AA$1,0),FALSE)) -> Arias Gomar, Ramon | C8: =IF(VLOOKUP($A8,Sheet1!$A:$AA,MATCH(C$1,Sheet1!$A$1:$AA$1,0),FALSE)=0,"",VLOOKUP($A8,Sheet1!$A:$AA,MATCH(C$1,Sheet1!$A$1:$AA$1,0),FALSE)) -> Arias Gomar | D8: =IF(VLOOKUP($A8,Sheet1!$A:$AA,MATCH(D$1,Sheet1!$A$1:$AA$1,0),FALSE)=0,"",VLOOKUP($A8,Sheet1!$A:$AA,MATCH(D$1,Sheet1!$A$1:$AA$1,0),FALSE)) -> Ramon | E8: =IF(VLOOKUP($A8,Sheet1!$A:$AA,MATCH(E$1,Sheet1!$A$1:$AA$1,0),FALSE)=0,"",VLOOKUP($A8,Sheet1!$A:$AA,MATCH(E$1,Sheet1!$A$1:$AA$1,0),FALSE)) -> Ramon Arias Gomar | F8: =IF(VLOOKUP($A8,Sheet1!$A:$AA,MATCH(F$1,Sheet1!$A$1:$AA$1,0),FALSE)=0,"",VLOOKUP($A8,Sheet1!$A:$AA,MATCH(F$1,Sheet1!$A$1:$AA$1,0),FALSE)) | G8: =IF(VLOOKUP($A8,Sheet1!$A:$AA,MATCH(G$1,Sheet1!$A$1:$AA$1,0),FALSE)=0,"",VLOOKUP($A8,Sheet1!$A:$AA,MATCH(G$1,Sheet1!$A$1:$AA$1,0),FALSE)) | H8: =IF(VLOOKUP($A8,Sheet1!$A:$AA,MATCH(H$1,Sheet1!$A$1:$AA$1,0),FALSE)=0,"",VLOOKUP($A8,Sheet1!$A:$AA,MATCH(H$1,Sheet1!$A$1:$AA$1,0),FALSE)) | I8: =IF(VLOOKUP($A8,Sheet1!$A:$AA,MATCH(I$1,Sheet1!$A$1:$AA$1,0),FALSE)=0,"",VLOOKUP($A8,Sheet1!$A:$AA,MATCH(I$1,Sheet1!$A$1:$AA$1,0),FALSE)) | ... AA8: =IF(VLOOKUP($A8,Sheet1!$A:$AA,MATCH(AA$1,Sheet1!$A$1:$AA$1,0),FALSE)=0,"",VLOOKUP($A8,Sheet1!$A:$AA,MATCH(AA$1,Sheet1!$A$1:$AA$1,0),FALSE))
A9: 6723903 | B9: =IF(VLOOKUP($A9,Sheet1!$A:$AA,MATCH(B$1,Sheet1!$A$1:$AA$1,0),FALSE)=0,"",VLOOKUP($A9,Sheet1!$A:$AA,MATCH(B$1,Sheet1!$A$1:$AA$1,0),FALSE)) -> De Rueda De Genover, Ignasi | C9: =IF(VLOOKUP($A9,Sheet1!$A:$AA,MATCH(C$1,Sheet1!$A$1:$AA$1,0),FALSE)=0,"",VLOOKUP($A9,Sheet1!$A:$AA,MATCH(C$1,Sheet1!$A$1:$AA$1,0),FALSE)) -> De Rueda De Genover | D9: =IF(VLOOKUP($A9,Sheet1!$A:$AA,MATCH(D$1,Sheet1!$A$1:$AA$1,0),FALSE)=0,"",VLOOKUP($A9,Sheet1!$A:$AA,MATCH(D$1,Sheet1!$A$1:$AA$1,0),FALSE)) -> Ignasi | E9: =IF(VLOOKUP($A9,Sheet1!$A:$AA,MATCH(E$1,Sheet1!$A$1:$AA$1,0),FALSE)=0,"",VLOOKUP($A9,Sheet1!$A:$AA,MATCH(E$1,Sheet1!$A$1:$AA$1,0),FALSE)) -> Ignasi De Rueda De Genover | F9: =IF(VLOOKUP($A9,Sheet1!$A:$AA,MATCH(F$1,Sheet1!$A$1:$AA$1,0),FALSE)=0,"",VLOOKUP($A9,Sheet1!$A:$AA,MATCH(F$1,Sheet1!$A$1:$AA$1,0),FALSE)) | G9: =IF(VLOOKUP($A9,Sheet1!$A:$AA,MATCH(G$1,Sheet1!$A$1:$AA$1,0),FALSE)=0,"",VLOOKUP($A9,Sheet1!$A:$AA,MATCH(G$1,Sheet1!$A$1:$AA$1,0),FALSE)) | H9: =IF(VLOOKUP($A9,Sheet1!$A:$AA,MATCH(H$1,Sheet1!$A$1:$AA$1,0),FALSE)=0,"",VLOOKUP($A9,Sheet1!$A:$AA,MATCH(H$1,Sheet1!$A$1:$AA$1,0),FALSE)) | I9: =IF(VLOOKUP($A9,Sheet1!$A:$AA,MATCH(I$1,Sheet1!$A$1:$AA$1,0),FALSE)=0,"",VLOOKUP($A9,Sheet1!$A:$AA,MATCH(I$1,Sheet1!$A$1:$AA$1,0),FALSE)) | ... AA9: =IF(VLOOKUP($A9,Sheet1!$A:$AA,MATCH(AA$1,Sheet1!$A$1:$AA$1,0),FALSE)=0,"",VLOOKUP($A9,Sheet1!$A:$AA,MATCH(AA$1,Sheet1!$A$1:$AA$1,0),FALSE))
A10: 16937065 | B10: =IF(VLOOKUP($A10,Sheet1!$A:$AA,MATCH(B$1,Sheet1!$A$1:$AA$1,0),FALSE)=0,"",VLOOKUP($A10,Sheet1!$A:$AA,MATCH(B$1,Sheet1!$A$1:$AA$1,0),FALSE)) -> Pereira de Mattos, Domini Elias | C10: =IF(VLOOKUP($A10,Sheet1!$A:$AA,MATCH(C$1,Sheet1!$A$1:$AA$1,0),FALSE)=0,"",VLOOKUP($A10,Sheet1!$A:$AA,MATCH(C$1,Sheet1!$A$1:$AA$1,0),FALSE)) -> Pereira de Mattos | D10: =IF(VLOOKUP($A10,Sheet1!$A:$AA,MATCH(D$1,Sheet1!$A$1:$AA$1,0),FALSE)=0,"",VLOOKUP($A10,Sheet1!$A:$AA,MATCH(D$1,Sheet1!$A$1:$AA$1,0),FALSE)) -> Domini Elias | E10: =IF(VLOOKUP($A10,Sheet1!$A:$AA,MATCH(E$1,Sheet1!$A$1:$AA$1,0),FALSE)=0,"",VLOOKUP($A10,Sheet1!$A:$AA,MATCH(E$1,Sheet1!$A$1:$AA$1,0),FALSE)) -> Domini Elias Pereira de Mattos | F10: =IF(VLOOKUP($A10,Sheet1!$A:$AA,MATCH(F$1,Sheet1!$A$1:$AA$1,0),FALSE)=0,"",VLOOKUP($A10,Sheet1!$A:$AA,MATCH(F$1,Sheet1!$A$1:$AA$1,0),FALSE)) | G10: =IF(VLOOKUP($A10,Sheet1!$A:$AA,MATCH(G$1,Sheet1!$A$1:$AA$1,0),FALSE)=0,"",VLOOKUP($A10,Sheet1!$A:$AA,MATCH(G$1,Sheet1!$A$1:$AA$1,0),FALSE)) | H10: =IF(VLOOKUP($A10,Sheet1!$A:$AA,MATCH(H$1,Sheet1!$A$1:$AA$1,0),FALSE)=0,"",VLOOKUP($A10,Sheet1!$A:$AA,MATCH(H$1,Sheet1!$A$1:$AA$1,0),FALSE)) | I10: =IF(VLOOKUP($A10,Sheet1!$A:$AA,MATCH(I$1,Sheet1!$A$1:$AA$1,0),FALSE)=0,"",VLOOKUP($A10,Sheet1!$A:$AA,MATCH(I$1,Sheet1!$A$1:$AA$1,0),FALSE)) | ... AA10: =IF(VLOOKUP($A10,Sheet1!$A:$AA,MATCH(AA$1,Sheet1!$A$1:$AA$1,0),FALSE)=0,"",VLOOKUP($A10,Sheet1!$A:$AA,MATCH(AA$1,Sheet1!$A$1:$AA$1,0),FALSE))
A11: 11855642 | B11: =IF(VLOOKUP($A11,Sheet1!$A:$AA,MATCH(B$1,Sheet1!$A$1:$AA$1,0),FALSE)=0,"",VLOOKUP($A11,Sheet1!$A:$AA,MATCH(B$1,Sheet1!$A$1:$AA$1,0),FALSE)) -> Caymel Romero, Marc | C11: =IF(VLOOKUP($A11,Sheet1!$A:$AA,MATCH(C$1,Sheet1!$A$1:$AA$1,0),FALSE)=0,"",VLOOKUP($A11,Sheet1!$A:$AA,MATCH(C$1,Sheet1!$A$1:$AA$1,0),FALSE)) -> Caymel Romero | D11: =IF(VLOOKUP($A11,Sheet1!$A:$AA,MATCH(D$1,Sheet1!$A$1:$AA$1,0),FALSE)=0,"",VLOOKUP($A11,Sheet1!$A:$AA,MATCH(D$1,Sheet1!$A$1:$AA$1,0),FALSE)) -> Marc | E11: =IF(VLOOKUP($A11,Sheet1!$A:$AA,MATCH(E$1,Sheet1!$A$1:$AA$1,0),FALSE)=0,"",VLOOKUP($A11,Sheet1!$A:$AA,MATCH(E$1,Sheet1!$A$1:$AA$1,0),FALSE)) -> Marc Caymel Romero | F11: =IF(VLOOKUP($A11,Sheet1!$A:$AA,MATCH(F$1,Sheet1!$A$1:$AA$1,0),FALSE)=0,"",VLOOKUP($A11,Sheet1!$A:$AA,MATCH(F$1,Sheet1!$A$1:$AA$1,0),FALSE)) | G11: =IF(VLOOKUP($A11,Sheet1!$A:$AA,MATCH(G$1,Sheet1!$A$1:$AA$1,0),FALSE)=0,"",VLOOKUP($A11,Sheet1!$A:$AA,MATCH(G$1,Sheet1!$A$1:$AA$1,0),FALSE)) | H11: =IF(VLOOKUP($A11,Sheet1!$A:$AA,MATCH(H$1,Sheet1!$A$1:$AA$1,0),FALSE)=0,"",VLOOKUP($A11,Sheet1!$A:$AA,MATCH(H$1,Sheet1!$A$1:$AA$1,0),FALSE)) | I11: =IF(VLOOKUP($A11,Sheet1!$A:$AA,MATCH(I$1,Sheet1!$A$1:$AA$1,0),FALSE)=0,"",VLOOKUP($A11,Sheet1!$A:$AA,MATCH(I$1,Sheet1!$A$1:$AA$1,0),FALSE)) | ... AA11: =IF(VLOOKUP($A11,Sheet1!$A:$AA,MATCH(AA$1,Sheet1!$A$1:$AA$1,0),FALSE)=0,"",VLOOKUP($A11,Sheet1!$A:$AA,MATCH(AA$1,Sheet1!$A$1:$AA$1,0),FALSE))
A12: 10768565 | B12: =IF(VLOOKUP($A12,Sheet1!$A:$AA,MATCH(B$1,Sheet1!$A$1:$AA$1,0),FALSE)=0,"",VLOOKUP($A12,Sheet1!$A:$AA,MATCH(B$1,Sheet1!$A$1:$AA$1,0),FALSE)) -> Ruiz Calvo, Javier | C12: =IF(VLOOKUP($A12,Sheet1!$A:$AA,MATCH(C$1,Sheet1!$A$1:$AA$1,0),FALSE)=0,"",VLOOKUP($A12,Sheet1!$A:$AA,MATCH(C$1,Sheet1!$A$1:$AA$1,0),FALSE)) -> Ruiz Calvo | D12: =IF(VLOOKUP($A12,Sheet1!$A:$AA,MATCH(D$1,Sheet1!$A$1:$AA$1,0),FALSE)=0,"",VLOOKUP($A12,Sheet1!$A:$AA,MATCH(D$1,Sheet1!$A$1:$AA$1,0),FALSE)) -> Javier | E12: =IF(VLOOKUP($A12,Sheet1!$A:$AA,MATCH(E$1,Sheet1!$A$1:$AA$1,0),FALSE)=0,"",VLOOKUP($A12,Sheet1!$A:$AA,MATCH(E$1,Sheet1!$A$1:$AA$1,0),FALSE)) -> Javier Ruiz Calvo | F12: =IF(VLOOKUP($A12,Sheet1!$A:$AA,MATCH(F$1,Sheet1!$A$1:$AA$1,0),FALSE)=0,"",VLOOKUP($A12,Sheet1!$A:$AA,MATCH(F$1,Sheet1!$A$1:$AA$1,0),FALSE)) | G12: =IF(VLOOKUP($A12,Sheet1!$A:$AA,MATCH(G$1,Sheet1!$A$1:$AA$1,0),FALSE)=0,"",VLOOKUP($A12,Sheet1!$A:$AA,MATCH(G$1,Sheet1!$A$1:$AA$1,0),FALSE)) | H12: =IF(VLOOKUP($A12,Sheet1!$A:$AA,MATCH(H$1,Sheet1!$A$1:$AA$1,0),FALSE)=0,"",VLOOKUP($A12,Sheet1!$A:$AA,MATCH(H$1,Sheet1!$A$1:$AA$1,0),FALSE)) | I12: =IF(VLOOKUP($A12,Sheet1!$A:$AA,MATCH(I$1,Sheet1!$A$1:$AA$1,0),FALSE)=0,"",VLOOKUP($A12,Sheet1!$A:$AA,MATCH(I$1,Sheet1!$A$1:$AA$1,0),FALSE)) | ... AA12: =IF(VLOOKUP($A12,Sheet1!$A:$AA,MATCH(AA$1,Sheet1!$A$1:$AA$1,0),FALSE)=0,"",VLOOKUP($A12,Sheet1!$A:$AA,MATCH(AA$1,Sheet1!$A$1:$AA$1,0),FALSE)) -> 42
A13: 10768929 | B13: =IF(VLOOKUP($A13,Sheet1!$A:$AA,MATCH(B$1,Sheet1!$A$1:$AA$1,0),FALSE)=0,"",VLOOKUP($A13,Sheet1!$A:$AA,MATCH(B$1,Sheet1!$A$1:$AA$1,0),FALSE)) -> Vega Gutierrez, Daniel | C13: =IF(VLOOKUP($A13,Sheet1!$A:$AA,MATCH(C$1,Sheet1!$A$1:$AA$1,0),FALSE)=0,"",VLOOKUP($A13,Sheet1!$A:$AA,MATCH(C$1,Sheet1!$A$1:$AA$1,0),FALSE)) -> Vega Gutierrez | D13: =IF(VLOOKUP($A13,Sheet1!$A:$AA,MATCH(D$1,Sheet1!$A$1:$AA$1,0),FALSE)=0,"",VLOOKUP($A13,Sheet1!$A:$AA,MATCH(D$1,Sheet1!$A$1:$AA$1,0),FALSE)) -> Daniel | E13: =IF(VLOOKUP($A13,Sheet1!$A:$AA,MATCH(E$1,Sheet1!$A$1:$AA$1,0),FALSE)=0,"",VLOOKUP($A13,Sheet1!$A:$AA,MATCH(E$1,Sheet1!$A$1:$AA$1,0),FALSE)) -> Daniel Vega Gutierrez | F13: =IF(VLOOKUP($A13,Sheet1!$A:$AA,MATCH(F$1,Sheet1!$A$1:$AA$1,0),FALSE)=0,"",VLOOKUP($A13,Sheet1!$A:$AA,MATCH(F$1,Sheet1!$A$1:$AA$1,0),FALSE)) | G13: =IF(VLOOKUP($A13,Sheet1!$A:$AA,MATCH(G$1,Sheet1!$A$1:$AA$1,0),FALSE)=0,"",VLOOKUP($A13,Sheet1!$A:$AA,MATCH(G$1,Sheet1!$A$1:$AA$1,0),FALSE)) | H13: =IF(VLOOKUP($A13,Sheet1!$A:$AA,MATCH(H$1,Sheet1!$A$1:$AA$1,0),FALSE)=0,"",VLOOKUP($A13,Sheet1!$A:$AA,MATCH(H$1,Sheet1!$A$1:$AA$1,0),FALSE)) | I13: =IF(VLOOKUP($A13,Sheet1!$A:$AA,MATCH(I$1,Sheet1!$A$1:$AA$1,0),FALSE)=0,"",VLOOKUP($A13,Sheet1!$A:$AA,MATCH(I$1,Sheet1!$A$1:$AA$1,0),FALSE)) | ... AA13: =IF(VLOOKUP($A13,Sheet1!$A:$AA,MATCH(AA$1,Sheet1!$A$1:$AA$1,0),FALSE)=0,"",VLOOKUP($A13,Sheet1!$A:$AA,MATCH(AA$1,Sheet1!$A$1:$AA$1,0),FALSE))
... A80: 10574095 | B80: =IF(VLOOKUP($A80,Sheet1!$A:$AA,MATCH(B$1,Sheet1!$A$1:$AA$1,0),FALSE)=0,"",VLOOKUP($A80,Sheet1!$A:$AA,MATCH(B$1,Sheet1!$A$1:$AA$1,0),FALSE)) -> Bilbao Areitio, Beatriz | C80: =IF(VLOOKUP($A80,Sheet1!$A:$AA,MATCH(C$1,Sheet1!$A$1:$AA$1,0),FALSE)=0,"",VLOOKUP($A80,Sheet1!$A:$AA,MATCH(C$1,Sheet1!$A$1:$AA$1,0),FALSE)) -> Bilbao Areitio | D80: =IF(VLOOKUP($A80,Sheet1!$A:$AA,MATCH(D$1,Sheet1!$A$1:$AA$1,0),FALSE)=0,"",VLOOKUP($A80,Sheet1!$A:$AA,MATCH(D$1,Sheet1!$A$1:$AA$1,0),FALSE)) -> Beatriz | E80: =IF(VLOOKUP($A80,Sheet1!$A:$AA,MATCH(E$1,Sheet1!$A$1:$AA$1,0),FALSE)=0,"",VLOOKUP($A80,Sheet1!$A:$AA,MATCH(E$1,Sheet1!$A$1:$AA$1,0),FALSE)) -> Beatriz Bilbao Areitio | F80: =IF(VLOOKUP($A80,Sheet1!$A:$AA,MATCH(F$1,Sheet1!$A$1:$AA$1,0),FALSE)=0,"",VLOOKUP($A80,Sheet1!$A:$AA,MATCH(F$1,Sheet1!$A$1:$AA$1,0),FALSE)) | G80: =IF(VLOOKUP($A80,Sheet1!$A:$AA,MATCH(G$1,Sheet1!$A$1:$AA$1,0),FALSE)=0,"",VLOOKUP($A80,Sheet1!$A:$AA,MATCH(G$1,Sheet1!$A$1:$AA$1,0),FALSE)) | H80: =IF(VLOOKUP($A80,Sheet1!$A:$AA,MATCH(H$1,Sheet1!$A$1:$AA$1,0),FALSE)=0,"",VLOOKUP($A80,Sheet1!$A:$AA,MATCH(H$1,Sheet1!$A$1:$AA$1,0),FALSE)) | I80: =IF(VLOOKUP($A80,Sheet1!$A:$AA,MATCH(I$1,Sheet1!$A$1:$AA$1,0),FALSE)=0,"",VLOOKUP($A80,Sheet1!$A:$AA,MATCH(I$1,Sheet1!$A$1:$AA$1,0),FALSE)) | ... AA80: =IF(VLOOKUP($A80,Sheet1!$A:$AA,MATCH(AA$1,Sheet1!$A$1:$AA$1,0),FALSE)=0,"",VLOOKUP($A80,Sheet1!$A:$AA,MATCH(AA$1,Sheet1!$A$1:$AA$1,0),FALSE)) -> 28
